Workbook
Name Список_Протокол: OFFSET(Справочники!$B$5,0,0,MAX(1,COUNTA(Справочники!$B$5:$B$104)),1)
Name Список_Действие_Торговля: OFFSET(Справочники!$C$5,0,0,MAX(1,COUNTA(Справочники!$C$5:$C$104)),1)

Sheet Ввод
B1: CRYPTO JOURNAL • ВВОД
B3: ОСНОВНЫЕ ДАННЫЕ
B4: Дата | C4: Актив 1 | D4: Актив 2 | E4: Пара (авто) | F4: Протокол | G4: Статус
B5: 46299 | C5: ETH | D5: BTC | E5: =IF(AND(TRIM(C5)<>"",TRIM(D5)<>""),UPPER(TRIM(C5))&"/"&UPPER(TRIM(D5)),"") | F5: Binance | G5: =IF((COUNTA($C$9,$C$10,$C$12,$C$13)>0)+(COUNTA($E$9,$E$10,$E$12,$E$13)>0)+(COUNTA($G$9:$G$13)>0)>1,"Два раздела",IF(COUNTA($C$9,$C$10,$C$12,$C$13)>0,IF(C8="","Нет действия",IF(NOT(ISNUMBER(C9)),"Нет Кол-ва",IF(C12="",IF(C13<>"","Нет ID",IF(NOT(ISNUMBER(C10)),"Нет курса","Новая позиция")),IF(ISNA(MATCH(C12,Торговля!$B$5:$B$300,0)),"Нет ID",IF(NOT(ISNUMBER(C10)),"Нет курса",IF(ISNUMBER(INDEX(Торговля!$F$5:$F$300,MATCH(C12,Торговля!$B$5:$B$300,0)))=(C8="Buy"),"Увеличение",IF(C13="Полностью","Закрытие полностью","Закрытие частично"))))))),IF(COUNTA($E$9,$E$10,$E$12,$E$13)>0,IF(E8="","Нет действия",IF(NOT(ISNUMBER(E9)),"Нет Кол-ва",IF(E12="",IF(E13<>"","Нет ID",IF(NOT(ISNUMBER(E10)),"Нет суммы","Новая позиция")),IF(ISNA(MATCH(E12,Лэндинг!$B$5:$B$300,0)),"Нет ID",IF(NOT(ISNUMBER(E10)),"Нет суммы",IF(ISNUMBER(INDEX(Лэндинг!$F$5:$F$300,MATCH(E12,Лэндинг!$B$5:$B$300,0)))=(E8="Buy"),"Увеличение",IF(E13="Полностью","Закрытие полностью","Закрытие частично"))))))),IF(COUNTA($G$9:$G$13)>0,IF(G8="","Нет действия",IF(OR(NOT(ISNUMBER(G10)),NOT(ISNUMBER(G11))),"Нет Кол-ва",IF(COUNT(G12,G13)=1,"Нужны Min и Max",IF(AND(G8="Добавить",G9=""),"Новый пул",IF(G9="","Нет ID пула",IF(ISNA(MATCH(G9,Пул!$B$5:$B$300,0)),"Нет ID пула",IF(INDEX(Пул!$L$5:$L$300,MATCH(G9,Пул!$B$5:$B$300,0))="Закрыт","Пул закрыт",IF(G8="Добавить","Добавить в пул",IF(G8="Частично","Частично","Закрытие пула"))))))))),"Готово"))))
B7: ТОРГОВЛЯ | D7: ЛЭНДИНГ | F7: ПУЛ
B8: Действие | C8: Buy | D8: Действие | E8: Buy | F8: Действие | G8: Добавить
B9: Кол-во | C9: 0.5 | D9: Кол-во | F9: ID пула
B10: Курс | C10: 62000 | D10: Сумма | F10: Кол-во 1
B11: Сумма (авто) | C11: =IF(AND(ISNUMBER(C9),ISNUMBER(C10),OR(C8="Buy",C8="Sell")),C9*C10*(1+IF(C8="Buy",1,-1)*N($E$17)/100),"") | D11: Курс (авто) | E11: =IF(AND(ISNUMBER(E9),ISNUMBER(E10),E9<>0),IF(E8="Buy",E10/(E9*(1+N($E$17)/100)),IF(AND(E8="Sell",1-N($E$17)/100<>0),E10/(E9*(1-N($E$17)/100)),"")),"") | F11: Кол-во 2
B12: ID позиции | C12: T-0001 | D12: ID позиции | F12: Min
B13: Закрыть | D13: Закрыть | F13: Max
B15: ОБРАТНЫЙ РАСЧЁТ
B16: Сумма | C16: Курс | D16: Кол-во (авто) | E16: Комиссия | F16: ЗАПИСАТЬ | G16: ОЧИСТИТЬ
B17: 31000 | C17: 62000 | D17: =IF(AND(ISNUMBER(B17),ISNUMBER(C17),C17<>0,1-N(E17)/100<>0),B17/(C17*(1-N(E17)/100)),"") | E17: 0.2
B19: Торговля / Лэндинг: ID пусто — новая позиция; ID и то же Действие (Buy к Buy) — увеличение; ID и противоположное — закрытие.
B20: Закрыть (только при ID): «Частично» списывает проданное Кол-во (пусто = Частично), «Полностью» закрывает весь остаток; разница с проданным остаётся прибылью в монетах.
B21: Торговля: курс биржевой, без комиссии (Комиссия E17 уже учитывается в курсе журнала). Лэндинг: вводятся Кол-во и Сумма.
B22: Пул: Min и Max — только для Web3 (могут быть дробными, меньше 1), оба поля или ни одного. Действия: Добавить, Частично (вывод части), Закрыть.
B23: ЗАПИСАТЬ переносит данные в журнал и очищает поля (Дата и Комиссия остаются). ОЧИСТИТЬ только очищает поля. Заполняется только один раздел.

Sheet Торговля
B1: CRYPTO JOURNAL • ТОРГОВЛЯ
B4: ID | C4: Дата | D4: Протокол | E4: Пара | F4: Покупка | G4: Курс | H4: Сумма | I4: Продажа | J4: Курс | K4: Сумма | L4: Дельта 1 | M4: Дельта 2 | N4: Break even
B5: T-0005 | C5: 46299 | D5: Bybit | E5: BNB/USDT | H5: =IF(AND(ISNUMBER(F5),ISNUMBER(G5)),F5*G5,"") | I5: 3 | J5: 598.8 | K5: =IF(AND(ISNUMBER(I5),ISNUMBER(J5)),I5*J5,"") | L5: =IF(COUNT(F5,I5)=0,"",N(F5)-N(I5)) | M5: =IF(COUNT(H5,K5)=0,"",N(K5)-N(H5)) | N5: =IF(AND(ISNUMBER(F5),ISNUMBER(G5),F5>0,1-N(Ввод!$E$17)/100>0),MAX(0,(F5*G5-SUMPRODUCT((Закрытые!$B$5:$B$300=$B5)*((Закрытые!$F$5:$F$300+Закрытые!$I$5:$I$300-ABS(Закрытые!$F$5:$F$300-Закрытые!$I$5:$I$300))/2)*(Закрытые!$J$5:$J$300-Закрытые!$G$5:$G$300)))/F5)/(1-N(Ввод!$E$17)/100),IF(AND(ISNUMBER(I5),ISNUMBER(J5),I5>0),MAX(0,(I5*J5+SUMPRODUCT((Закрытые!$B$5:$B$300=$B5)*((Закрытые!$F$5:$F$300+Закрытые!$I$5:$I$300-ABS(Закрытые!$F$5:$F$300-Закрытые!$I$5:$I$300))/2)*(Закрытые!$J$5:$J$300-Закрытые!$G$5:$G$300)))/I5)/(1+N(Ввод!$E$17)/100),""))
B6: T-0001 | C6: 46296 | D6: Binance | E6: BTC/USDT | F6: 0.1 | G6: 62124 | H6: =IF(AND(ISNUMBER(F6),ISNUMBER(G6)),F6*G6,"") | K6: =IF(AND(ISNUMBER(I6),ISNUMBER(J6)),I6*J6,"") | L6: =IF(COUNT(F6,I6)=0,"",N(F6)-N(I6)) | M6: =IF(COUNT(H6,K6)=0,"",N(K6)-N(H6)) | N6: =IF(AND(ISNUMBER(F6),ISNUMBER(G6),F6>0,1-N(Ввод!$E$17)/100>0),MAX(0,(F6*G6-SUMPRODUCT((Закрытые!$B$5:$B$300=$B6)*((Закрытые!$F$5:$F$300+Закрытые!$I$5:$I$300-ABS(Закрытые!$F$5:$F$300-Закрытые!$I$5:$I$300))/2)*(Закрытые!$J$5:$J$300-Закрытые!$G$5:$G$300)))/F6)/(1-N(Ввод!$E$17)/100),IF(AND(ISNUMBER(I6),ISNUMBER(J6),I6>0),MAX(0,(I6*J6+SUMPRODUCT((Закрытые!$B$5:$B$300=$B6)*((Закрытые!$F$5:$F$300+Закрытые!$I$5:$I$300-ABS(Закрытые!$F$5:$F$300-Закрытые!$I$5:$I$300))/2)*(Закрытые!$J$5:$J$300-Закрытые!$G$5:$G$300)))/I6)/(1+N(Ввод!$E$17)/100),""))
B7: T-0004 | C7: 46298 | D7: Binance | E7: ETH/BTC | H7: =IF(AND(ISNUMBER(F7),ISNUMBER(G7)),F7*G7,"") | I7: 1.5 | J7: 0.052395 | K7: =IF(AND(ISNUMBER(I7),ISNUMBER(J7)),I7*J7,"") | L7: =IF(COUNT(F7,I7)=0,"",N(F7)-N(I7)) | M7: =IF(COUNT(H7,K7)=0,"",N(K7)-N(H7)) | N7: =IF(AND(ISNUMBER(F7),ISNUMBER(G7),F7>0,1-N(Ввод!$E$17)/100>0),MAX(0,(F7*G7-SUMPRODUCT((Закрытые!$B$5:$B$300=$B7)*((Закрытые!$F$5:$F$300+Закрытые!$I$5:$I$300-ABS(Закрытые!$F$5:$F$300-Закрытые!$I$5:$I$300))/2)*(Закрытые!$J$5:$J$300-Закрытые!$G$5:$G$300)))/F7)/(1-N(Ввод!$E$17)/100),IF(AND(ISNUMBER(I7),ISNUMBER(J7),I7>0),MAX(0,(I7*J7+SUMPRODUCT((Закрытые!$B$5:$B$300=$B7)*((Закрытые!$F$5:$F$300+Закрытые!$I$5:$I$300-ABS(Закрытые!$F$5:$F$300-Закрытые!$I$5:$I$300))/2)*(Закрытые!$J$5:$J$300-Закрытые!$G$5:$G$300)))/I7)/(1+N(Ввод!$E$17)/100),""))
B8: T-0002 | C8: 46297 | D8: Bybit | E8: ETH/USDT | F8: 1 | G8: 3206.4 | H8: =IF(AND(ISNUMBER(F8),ISNUMBER(G8)),F8*G8,"") | K8: =IF(AND(ISNUMBER(I8),ISNUMBER(J8)),I8*J8,"") | L8: =IF(COUNT(F8,I8)=0,"",N(F8)-N(I8)) | M8: =IF(COUNT(H8,K8)=0,"",N(K8)-N(H8)) | N8: =IF(AND(ISNUMBER(F8),ISNUMBER(G8),F8>0,1-N(Ввод!$E$17)/100>0),MAX(0,(F8*G8-SUMPRODUCT((Закрытые!$B$5:$B$300=$B8)*((Закрытые!$F$5:$F$300+Закрытые!$I$5:$I$300-ABS(Закрытые!$F$5:$F$300-Закрытые!$I$5:$I$300))/2)*(Закрытые!$J$5:$J$300-Закрытые!$G$5:$G$300)))/F8)/(1-N(Ввод!$E$17)/100),IF(AND(ISNUMBER(I8),ISNUMBER(J8),I8>0),MAX(0,(I8*J8+SUMPRODUCT((Закрытые!$B$5:$B$300=$B8)*((Закрытые!$F$5:$F$300+Закрытые!$I$5:$I$300-ABS(Закрытые!$F$5:$F$300-Закрытые!$I$5:$I$300))/2)*(Закрытые!$J$5:$J$300-Закрытые!$G$5:$G$300)))/I8)/(1+N(Ввод!$E$17)/100),""))
B9: T-0007 | C9: 46300 | D9: Binance | E9: ETH/USDT | F9: 1.2 | G9: 3186.36 | H9: =IF(AND(ISNUMBER(F9),ISNUMBER(G9)),F9*G9,"") | K9: =IF(AND(ISNUMBER(I9),ISNUMBER(J9)),I9*J9,"") | L9: =IF(COUNT(F9,I9)=0,"",N(F9)-N(I9)) | M9: =IF(COUNT(H9,K9)=0,"",N(K9)-N(H9)) | N9: =IF(AND(ISNUMBER(F9),ISNUMBER(G9),F9>0,1-N(Ввод!$E$17)/100>0),MAX(0,(F9*G9-SUMPRODUCT((Закрытые!$B$5:$B$300=$B9)*((Закрытые!$F$5:$F$300+Закрытые!$I$5:$I$300-ABS(Закрытые!$F$5:$F$300-Закрытые!$I$5:$I$300))/2)*(Закрытые!$J$5:$J$300-Закрытые!$G$5:$G$300)))/F9)/(1-N(Ввод!$E$17)/100),IF(AND(ISNUMBER(I9),ISNUMBER(J9),I9>0),MAX(0,(I9*J9+SUMPRODUCT((Закрытые!$B$5:$B$300=$B9)*((Закрытые!$F$5:$F$300+Закрытые!$I$5:$I$300-ABS(Закрытые!$F$5:$F$300-Закрытые!$I$5:$I$300))/2)*(Закрытые!$J$5:$J$300-Закрытые!$G$5:$G$300)))/I9)/(1+N(Ввод!$E$17)/100),""))
B10: T-0008 | C10: 46300 | D10: Bybit | E10: ETH/USDT | F10: 0.8 | G10: 3256.5 | H10: =IF(AND(ISNUMBER(F10),ISNUMBER(G10)),F10*G10,"") | K10: =IF(AND(ISNUMBER(I10),ISNUMBER(J10)),I10*J10,"") | L10: =IF(COUNT(F10,I10)=0,"",N(F10)-N(I10)) | M10: =IF(COUNT(H10,K10)=0,"",N(K10)-N(H10)) | N10: =IF(AND(ISNUMBER(F10),ISNUMBER(G10),F10>0,1-N(Ввод!$E$17)/100>0),MAX(0,(F10*G10-SUMPRODUCT((Закрытые!$B$5:$B$300=$B10)*((Закрытые!$F$5:$F$300+Закрытые!$I$5:$I$300-ABS(Закрытые!$F$5:$F$300-Закрытые!$I$5:$I$300))/2)*(Закрытые!$J$5:$J$300-Закрытые!$G$5:$G$300)))/F10)/(1-N(Ввод!$E$17)/100),IF(AND(ISNUMBER(I10),ISNUMBER(J10),I10>0),MAX(0,(I10*J10+SUMPRODUCT((Закрытые!$B$5:$B$300=$B10)*((Закрытые!$F$5:$F$300+Закрытые!$I$5:$I$300-ABS(Закрытые!$F$5:$F$300-Закрытые!$I$5:$I$300))/2)*(Закрытые!$J$5:$J$300-Закрытые!$G$5:$G$300)))/I10)/(1+N(Ввод!$E$17)/100),""))
B11: T-0009 | C11: 46301 | D11: OKX | E11: ETH/USDT | H11: =IF(AND(ISNUMBER(F11),ISNUMBER(G11)),F11*G11,"") | I11: 1.5 | J11: 3393.2 | K11: =IF(AND(ISNUMBER(I11),ISNUMBER(J11)),I11*J11,"") | L11: =IF(COUNT(F11,I11)=0,"",N(F11)-N(I11)) | M11: =IF(COUNT(H11,K11)=0,"",N(K11)-N(H11)) | N11: =IF(AND(ISNUMBER(F11),ISNUMBER(G11),F11>0,1-N(Ввод!$E$17)/100>0),MAX(0,(F11*G11-SUMPRODUCT((Закрытые!$B$5:$B$300=$B11)*((Закрытые!$F$5:$F$300+Закрытые!$I$5:$I$300-ABS(Закрытые!$F$5:$F$300-Закрытые!$I$5:$I$300))/2)*(Закрытые!$J$5:$J$300-Закрытые!$G$5:$G$300)))/F11)/(1-N(Ввод!$E$17)/100),IF(AND(ISNUMBER(I11),ISNUMBER(J11),I11>0),MAX(0,(I11*J11+SUMPRODUCT((Закрытые!$B$5:$B$300=$B11)*((Закрытые!$F$5:$F$300+Закрытые!$I$5:$I$300-ABS(Закрытые!$F$5:$F$300-Закрытые!$I$5:$I$300))/2)*(Закрытые!$J$5:$J$300-Закрытые!$G$5:$G$300)))/I11)/(1+N(Ввод!$E$17)/100),""))
B12: T-0010 | C12: 46300 | D12: Binance | E12: SOL/USDT | H12: =IF(AND(ISNUMBER(F12),ISNUMBER(G12)),F12*G12,"") | I12: 30 | J12: 149.7 | K12: =IF(AND(ISNUMBER(I12),ISNUMBER(J12)),I12*J12,"") | L12: =IF(COUNT(F12,I12)=0,"",N(F12)-N(I12)) | M12: =IF(COUNT(H12,K12)=0,"",N(K12)-N(H12)) | N12: =IF(AND(ISNUMBER(F12),ISNUMBER(G12),F12>0,1-N(Ввод!$E$17)/100>0),MAX(0,(F12*G12-SUMPRODUCT((Закрытые!$B$5:$B$300=$B12)*((Закрытые!$F$5:$F$300+Закрытые!$I$5:$I$300-ABS(Закрытые!$F$5:$F$300-Закрытые!$I$5:$I$300))/2)*(Закрытые!$J$5:$J$300-Закрытые!$G$5:$G$300)))/F12)/(1-N(Ввод!$E$17)/100),IF(AND(ISNUMBER(I12),ISNUMBER(J12),I12>0),MAX(0,(I12*J12+SUMPRODUCT((Закрытые!$B$5:$B$300=$B12)*((Закрытые!$F$5:$F$300+Закрытые!$I$5:$I$300-ABS(Закрытые!$F$5:$F$300-Закрытые!$I$5:$I$300))/2)*(Закрытые!$J$5:$J$300-Закрытые!$G$5:$G$300)))/I12)/(1+N(Ввод!$E$17)/100),""))
B13: T-0011 | C13: 46301 | D13: Bybit | E13: SOL/USDT | H13: =IF(AND(ISNUMBER(F13),ISNUMBER(G13)),F13*G13,"") | I13: 10 | J13: 151.696 | K13: =IF(AND(ISNUMBER(I13),ISNUMBER(J13)),I13*J13,"") | L13: =IF(COUNT(F13,I13)=0,"",N(F13)-N(I13)) | M13: =IF(COUNT(H13,K13)=0,"",N(K13)-N(H13)) | N13: =IF(AND(ISNUMBER(F13),ISNUMBER(G13),F13>0,1-N(Ввод!$E$17)/100>0),MAX(0,(F13*G13-SUMPRODUCT((Закрытые!$B$5:$B$300=$B13)*((Закрытые!$F$5:$F$300+Закрытые!$I$5:$I$300-ABS(Закрытые!$F$5:$F$300-Закрытые!$I$5:$I$300))/2)*(Закрытые!$J$5:$J$300-Закрытые!$G$5:$G$300)))/F13)/(1-N(Ввод!$E$17)/100),IF(AND(ISNUMBER(I13),ISNUMBER(J13),I13>0),MAX(0,(I13*J13+SUMPRODUCT((Закрытые!$B$5:$B$300=$B13)*((Закрытые!$F$5:$F$300+Закрытые!$I$5:$I$300-ABS(Закрытые!$F$5:$F$300-Закрытые!$I$5:$I$300))/2)*(Закрытые!$J$5:$J$300-Закрытые!$G$5:$G$300)))/I13)/(1+N(Ввод!$E$17)/100),""))
B14: T-0012 | C14: 46301 | D14: OKX | E14: SOL/USDT | F14: 25 | G14: 146.292 | H14: =IF(AND(ISNUMBER(F14),ISNUMBER(G14)),F14*G14,"") | K14: =IF(AND(ISNUMBER(I14),ISNUMBER(J14)),I14*J14,"") | L14: =IF(COUNT(F14,I14)=0,"",N(F14)-N(I14)) | M14: =IF(COUNT(H14,K14)=0,"",N(K14)-N(H14)) | N14: =IF(AND(ISNUMBER(F14),ISNUMBER(G14),F14>0,1-N(Ввод!$E$17)/100>0),MAX(0,(F14*G14-SUMPRODUCT((Закрытые!$B$5:$B$300=$B14)*((Закрытые!$F$5:$F$300+Закрытые!$I$5:$I$300-ABS(Закрытые!$F$5:$F$300-Закрытые!$I$5:$I$300))/2)*(Закрытые!$J$5:$J$300-Закрытые!$G$5:$G$300)))/F14)/(1-N(Ввод!$E$17)/100),IF(AND(ISNUMBER(I14),ISNUMBER(J14),I14>0),MAX(0,(I14*J14+SUMPRODUCT((Закрытые!$B$5:$B$300=$B14)*((Закрытые!$F$5:$F$300+Закрытые!$I$5:$I$300-ABS(Закрытые!$F$5:$F$300-Закрытые!$I$5:$I$300))/2)*(Закрытые!$J$5:$J$300-Закрытые!$G$5:$G$300)))/I14)/(1+N(Ввод!$E$17)/100),""))
B15: T-0013 | C15: 46302 | D15: Binance | E15: AAVE/ETH | F15: 20 | G15: 0.062625 | H15: =IF(AND(ISNUMBER(F15),ISNUMBER(G15)),F15*G15,"") | K15: =IF(AND(ISNUMBER(I15),ISNUMBER(J15)),I15*J15,"") | L15: =IF(COUNT(F15,I15)=0,"",N(F15)-N(I15)) | M15: =IF(COUNT(H15,K15)=0,"",N(K15)-N(H15)) | N15: =IF(AND(ISNUMBER(F15),ISNUMBER(G15),F15>0,1-N(Ввод!$E$17)/100>0),MAX(0,(F15*G15-SUMPRODUCT((Закрытые!$B$5:$B$300=$B15)*((Закрытые!$F$5:$F$300+Закрытые!$I$5:$I$300-ABS(Закрытые!$F$5:$F$300-Закрытые!$I$5:$I$300))/2)*(Закрытые!$J$5:$J$300-Закрытые!$G$5:$G$300)))/F15)/(1-N(Ввод!$E$17)/100),IF(AND(ISNUMBER(I15),ISNUMBER(J15),I15>0),MAX(0,(I15*J15+SUMPRODUCT((Закрытые!$B$5:$B$300=$B15)*((Закрытые!$F$5:$F$300+Закрытые!$I$5:$I$300-ABS(Закрытые!$F$5:$F$300-Закрытые!$I$5:$I$300))/2)*(Закрытые!$J$5:$J$300-Закрытые!$G$5:$G$300)))/I15)/(1+N(Ввод!$E$17)/100),""))
B16: T-0014 | C16: 46302 | D16: Bybit | E16: DOGE/BTC | H16: =IF(AND(ISNUMBER(F16),ISNUMBER(G16)),F16*G16,"") | I16: 100000 | J16: 2.89e-06 | K16: =IF(AND(ISNUMBER(I16),ISNUMBER(J16)),I16*J16,"") | L16: =IF(COUNT(F16,I16)=0,"",N(F16)-N(I16)) | M16: =IF(COUNT(H16,K16)=0,"",N(K16)-N(H16)) | N16: =IF(AND(ISNUMBER(F16),ISNUMBER(G16),F16>0,1-N(Ввод!$E$17)/100>0),MAX(0,(F16*G16-SUMPRODUCT((Закрытые!$B$5:$B$300=$B16)*((Закрытые!$F$5:$F$300+Закрытые!$I$5:$I$300-ABS(Закрытые!$F$5:$F$300-Закрытые!$I$5:$I$300))/2)*(Закрытые!$J$5:$J$300-Закрытые!$G$5:$G$300)))/F16)/(1-N(Ввод!$E$17)/100),IF(AND(ISNUMBER(I16),ISNUMBER(J16),I16>0),MAX(0,(I16*J16+SUMPRODUCT((Закрытые!$B$5:$B$300=$B16)*((Закрытые!$F$5:$F$300+Закрытые!$I$5:$I$300-ABS(Закрытые!$F$5:$F$300-Закрытые!$I$5:$I$300))/2)*(Закрытые!$J$5:$J$300-Закрытые!$G$5:$G$300)))/I16)/(1+N(Ввод!$E$17)/100),""))
B17: T-0015 | C17: 46302 | D17: OKX | E17: LTC/BCH | F17: 50 | G17: 0.2004 | H17: =IF(AND(ISNUMBER(F17),ISNUMBER(G17)),F17*G17,"") | K17: =IF(AND(ISNUMBER(I17),ISNUMBER(J17)),I17*J17,"") | L17: =IF(COUNT(F17,I17)=0,"",N(F17)-N(I17)) | M17: =IF(COUNT(H17,K17)=0,"",N(K17)-N(H17)) | N17: =IF(AND(ISNUMBER(F17),ISNUMBER(G17),F17>0,1-N(Ввод!$E$17)/100>0),MAX(0,(F17*G17-SUMPRODUCT((Закрытые!$B$5:$B$300=$B17)*((Закрытые!$F$5:$F$300+Закрытые!$I$5:$I$300-ABS(Закрытые!$F$5:$F$300-Закрытые!$I$5:$I$300))/2)*(Закрытые!$J$5:$J$300-Закрытые!$G$5:$G$300)))/F17)/(1-N(Ввод!$E$17)/100),IF(AND(ISNUMBER(I17),ISNUMBER(J17),I17>0),MAX(0,(I17*J17+SUMPRODUCT((Закрытые!$B$5:$B$300=$B17)*((Закрытые!$F$5:$F$300+Закрытые!$I$5:$I$300-ABS(Закрытые!$F$5:$F$300-Закрытые!$I$5:$I$300))/2)*(Закрытые!$J$5:$J$300-Закрытые!$G$5:$G$300)))/I17)/(1+N(Ввод!$E$17)/100),""))
B18: T-0016 | C18: 46302 | D18: Binance | E18: XRP/TRX | H18: =IF(AND(ISNUMBER(F18),ISNUMBER(G18)),F18*G18,"") | I18: 3000 | J18: 8.1337 | K18: =IF(AND(ISNUMBER(I18),ISNUMBER(J18)),I18*J18,"") | L18: =IF(COUNT(F18,I18)=0,"",N(F18)-N(I18)) | M18: =IF(COUNT(H18,K18)=0,"",N(K18)-N(H18)) | N18: =IF(AND(ISNUMBER(F18),ISNUMBER(G18),F18>0,1-N(Ввод!$E$17)/100>0),MAX(0,(F18*G18-SUMPRODUCT((Закрытые!$B$5:$B$300=$B18)*((Закрытые!$F$5:$F$300+Закрытые!$I$5:$I$300-ABS(Закрытые!$F$5:$F$300-Закрытые!$I$5:$I$300))/2)*(Закрытые!$J$5:$J$300-Закрытые!$G$5:$G$300)))/F18)/(1-N(Ввод!$E$17)/100),IF(AND(ISNUMBER(I18),ISNUMBER(J18),I18>0),MAX(0,(I18*J18+SUMPRODUCT((Закрытые!$B$5:$B$300=$B18)*((Закрытые!$F$5:$F$300+Закрытые!$I$5:$I$300-ABS(Закрытые!$F$5:$F$300-Закрытые!$I$5:$I$300))/2)*(Закрытые!$J$5:$J$300-Закрытые!$G$5:$G$300)))/I18)/(1+N(Ввод!$E$17)/100),""))
B19: T-0017 | C19: 46302 | D19: Bybit | E19: SOL/USDT | F19: 40 | G19: 150.3 | H19: =IF(AND(ISNUMBER(F19),ISNUMBER(G19)),F19*G19,"") | K19: =IF(AND(ISNUMBER(I19),ISNUMBER(J19)),I19*J19,"") | L19: =IF(COUNT(F19,I19)=0,"",N(F19)-N(I19)) | M19: =IF(COUNT(H19,K19)=0,"",N(K19)-N(H19)) | N19: =IF(AND(ISNUMBER(F19),ISNUMBER(G19),F19>0,1-N(Ввод!$E$17)/100>0),MAX(0,(F19*G19-SUMPRODUCT((Закрытые!$B$5:$B$300=$B19)*((Закрытые!$F$5:$F$300+Закрытые!$I$5:$I$300-ABS(Закрытые!$F$5:$F$300-Закрытые!$I$5:$I$300))/2)*(Закрытые!$J$5:$J$300-Закрытые!$G$5:$G$300)))/F19)/(1-N(Ввод!$E$17)/100),IF(AND(ISNUMBER(I19),ISNUMBER(J19),I19>0),MAX(0,(I19*J19+SUMPRODUCT((Закрытые!$B$5:$B$300=$B19)*((Закрытые!$F$5:$F$300+Закрытые!$I$5:$I$300-ABS(Закрытые!$F$5:$F$300-Закрытые!$I$5:$I$300))/2)*(Закрытые!$J$5:$J$300-Закрытые!$G$5:$G$300)))/I19)/(1+N(Ввод!$E$17)/100),""))
B20: T-0023 | C20: 46303 | D20: Binance | E20: BNB/ETH | F20: 6 | G20: 0.187875 | H20: =IF(AND(ISNUMBER(F20),ISNUMBER(G20)),F20*G20,"") | K20: =IF(AND(ISNUMBER(I20),ISNUMBER(J20)),I20*J20,"") | L20: =IF(COUNT(F20,I20)=0,"",N(F20)-N(I20)) | M20: =IF(COUNT(H20,K20)=0,"",N(K20)-N(H20)) | N20: =IF(AND(ISNUMBER(F20),ISNUMBER(G20),F20>0,1-N(Ввод!$E$17)/100>0),MAX(0,(F20*G20-SUMPRODUCT((Закрытые!$B$5:$B$300=$B20)*((Закрытые!$F$5:$F$300+Закрытые!$I$5:$I$300-ABS(Закрытые!$F$5:$F$300-Закрытые!$I$5:$I$300))/2)*(Закрытые!$J$5:$J$300-Закрытые!$G$5:$G$300)))/F20)/(1-N(Ввод!$E$17)/100),IF(AND(ISNUMBER(I20),ISNUMBER(J20),I20>0),MAX(0,(I20*J20+SUMPRODUCT((Закрытые!$B$5:$B$300=$B20)*((Закрытые!$F$5:$F$300+Закрытые!$I$5:$I$300-ABS(Закрытые!$F$5:$F$300-Закрытые!$I$5:$I$300))/2)*(Закрытые!$J$5:$J$300-Закрытые!$G$5:$G$300)))/I20)/(1+N(Ввод!$E$17)/100),""))
B21: T-0024 | C21: 46303 | D21: Bybit | E21: BNB/BTC | H21: =IF(AND(ISNUMBER(F21),ISNUMBER(G21)),F21*G21,"") | I21: 5 | J21: 0.00966064 | K21: =IF(AND(ISNUMBER(I21),ISNUMBER(J21)),I21*J21,"") | L21: =IF(COUNT(F21,I21)=0,"",N(F21)-N(I21)) | M21: =IF(COUNT(H21,K21)=0,"",N(K21)-N(H21)) | N21: =IF(AND(ISNUMBER(F21),ISNUMBER(G21),F21>0,1-N(Ввод!$E$17)/100>0),MAX(0,(F21*G21-SUMPRODUCT((Закрытые!$B$5:$B$300=$B21)*((Закрытые!$F$5:$F$300+Закрытые!$I$5:$I$300-ABS(Закрытые!$F$5:$F$300-Закрытые!$I$5:$I$300))/2)*(Закрытые!$J$5:$J$300-Закрытые!$G$5:$G$300)))/F21)/(1-N(Ввод!$E$17)/100),IF(AND(ISNUMBER(I21),ISNUMBER(J21),I21>0),MAX(0,(I21*J21+SUMPRODUCT((Закрытые!$B$5:$B$300=$B21)*((Закрытые!$F$5:$F$300+Закрытые!$I$5:$I$300-ABS(Закрытые!$F$5:$F$300-Закрытые!$I$5:$I$300))/2)*(Закрытые!$J$5:$J$300-Закрытые!$G$5:$G$300)))/I21)/(1+N(Ввод!$E$17)/100),""))
B22: T-0025 | C22: 46303 | D22: OKX | E22: CAKE/ETH | F22: 350 | G22: 0.0007515 | H22: =IF(AND(ISNUMBER(F22),ISNUMBER(G22)),F22*G22,"") | K22: =IF(AND(ISNUMBER(I22),ISNUMBER(J22)),I22*J22,"") | L22: =IF(COUNT(F22,I22)=0,"",N(F22)-N(I22)) | M22: =IF(COUNT(H22,K22)=0,"",N(K22)-N(H22)) | N22: =IF(AND(ISNUMBER(F22),ISNUMBER(G22),F22>0,1-N(Ввод!$E$17)/100>0),MAX(0,(F22*G22-SUMPRODUCT((Закрытые!$B$5:$B$300=$B22)*((Закрытые!$F$5:$F$300+Закрытые!$I$5:$I$300-ABS(Закрытые!$F$5:$F$300-Закрытые!$I$5:$I$300))/2)*(Закрытые!$J$5:$J$300-Закрытые!$G$5:$G$300)))/F22)/(1-N(Ввод!$E$17)/100),IF(AND(ISNUMBER(I22),ISNUMBER(J22),I22>0),MAX(0,(I22*J22+SUMPRODUCT((Закрытые!$B$5:$B$300=$B22)*((Закрытые!$F$5:$F$300+Закрытые!$I$5:$I$300-ABS(Закрытые!$F$5:$F$300-Закрытые!$I$5:$I$300))/2)*(Закрытые!$J$5:$J$300-Закрытые!$G$5:$G$300)))/I22)/(1+N(Ввод!$E$17)/100),""))
B23: T-0026 | C23: 46303 | D23: Binance | E23: DASH/BTC | F23: 18 | G23: 0.00061423 | H23: =IF(AND(ISNUMBER(F23),ISNUMBER(G23)),F23*G23,"") | K23: =IF(AND(ISNUMBER(I23),ISNUMBER(J23)),I23*J23,"") | L23: =IF(COUNT(F23,I23)=0,"",N(F23)-N(I23)) | M23: =IF(COUNT(H23,K23)=0,"",N(K23)-N(H23)) | N23: =IF(AND(ISNUMBER(F23),ISNUMBER(G23),F23>0,1-N(Ввод!$E$17)/100>0),MAX(0,(F23*G23-SUMPRODUCT((Закрытые!$B$5:$B$300=$B23)*((Закрытые!$F$5:$F$300+Закрытые!$I$5:$I$300-ABS(Закрытые!$F$5:$F$300-Закрытые!$I$5:$I$300))/2)*(Закрытые!$J$5:$J$300-Закрытые!$G$5:$G$300)))/F23)/(1-N(Ввод!$E$17)/100),IF(AND(ISNUMBER(I23),ISNUMBER(J23),I23>0),MAX(0,(I23*J23+SUMPRODUCT((Закрытые!$B$5:$B$300=$B23)*((Закрытые!$F$5:$F$300+Закрытые!$I$5:$I$300-ABS(Закрытые!$F$5:$F$300-Закрытые!$I$5:$I$300))/2)*(Закрытые!$J$5:$J$300-Закрытые!$G$5:$G$300)))/I23)/(1+N(Ввод!$E$17)/100),""))
B24: T-0027 | C24: 46304 | D24: Bybit | E24: DASH/LTC | H24: =IF(AND(ISNUMBER(F24),ISNUMBER(G24)),F24*G24,"") | I24: 30 | J24: 0.4213556 | K24: =IF(AND(ISNUMBER(I24),ISNUMBER(J24)),I24*J24,"") | L24: =IF(COUNT(F24,I24)=0,"",N(F24)-N(I24)) | M24: =IF(COUNT(H24,K24)=0,"",N(K24)-N(H24)) | N24: =IF(AND(ISNUMBER(F24),ISNUMBER(G24),F24>0,1-N(Ввод!$E$17)/100>0),MAX(0,(F24*G24-SUMPRODUCT((Закрытые!$B$5:$B$300=$B24)*((Закрытые!$F$5:$F$300+Закрытые!$I$5:$I$300-ABS(Закрытые!$F$5:$F$300-Закрытые!$I$5:$I$300))/2)*(Закрытые!$J$5:$J$300-Закрытые!$G$5:$G$300)))/F24)/(1-N(Ввод!$E$17)/100),IF(AND(ISNUMBER(I24),ISNUMBER(J24),I24>0),MAX(0,(I24*J24+SUMPRODUCT((Закрытые!$B$5:$B$300=$B24)*((Закрытые!$F$5:$F$300+Закрытые!$I$5:$I$300-ABS(Закрытые!$F$5:$F$300-Закрытые!$I$5:$I$300))/2)*(Закрытые!$J$5:$J$300-Закрытые!$G$5:$G$300)))/I24)/(1+N(Ввод!$E$17)/100),""))
B25: T-0029 | C25: 46303 | D25: Bybit | E25: SOL/USDT | F25: 12 | G25: 150.3 | H25: =IF(AND(ISNUMBER(F25),ISNUMBER(G25)),F25*G25,"") | K25: =IF(AND(ISNUMBER(I25),ISNUMBER(J25)),I25*J25,"") | L25: =IF(COUNT(F25,I25)=0,"",N(F25)-N(I25)) | M25: =IF(COUNT(H25,K25)=0,"",N(K25)-N(H25)) | N25: =IF(AND(ISNUMBER(F25),ISNUMBER(G25),F25>0,1-N(Ввод!$E$17)/100>0),MAX(0,(F25*G25-SUMPRODUCT((Закрытые!$B$5:$B$300=$B25)*((Закрытые!$F$5:$F$300+Закрытые!$I$5:$I$300-ABS(Закрытые!$F$5:$F$300-Закрытые!$I$5:$I$300))/2)*(Закрытые!$J$5:$J$300-Закрытые!$G$5:$G$300)))/F25)/(1-N(Ввод!$E$17)/100),IF(AND(ISNUMBER(I25),ISNUMBER(J25),I25>0),MAX(0,(I25*J25+SUMPRODUCT((Закрытые!$B$5:$B$300=$B25)*((Закрытые!$F$5:$F$300+Закрытые!$I$5:$I$300-ABS(Закрытые!$F$5:$F$300-Закрытые!$I$5:$I$300))/2)*(Закрытые!$J$5:$J$300-Закрытые!$G$5:$G$300)))/I25)/(1+N(Ввод!$E$17)/100),""))
H26: =IF(AND(ISNUMBER(F26),ISNUMBER(G26)),F26*G26,"") | K26: =IF(AND(ISNUMBER(I26),ISNUMBER(J26)),I26*J26,"") | L26: =IF(COUNT(F26,I26)=0,"",N(F26)-N(I26)) | M26: =IF(COUNT(H26,K26)=0,"",N(K26)-N(H26)) | N26: =IF(AND(ISNUMBER(F26),ISNUMBER(G26),F26>0,1-N(Ввод!$E$17)/100>0),MAX(0,(F26*G26-SUMPRODUCT((Закрытые!$B$5:$B$300=$B26)*((Закрытые!$F$5:$F$300+Закрытые!$I$5:$I$300-ABS(Закрытые!$F$5:$F$300-Закрытые!$I$5:$I$300))/2)*(Закрытые!$J$5:$J$300-Закрытые!$G$5:$G$300)))/F26)/(1-N(Ввод!$E$17)/100),IF(AND(ISNUMBER(I26),ISNUMBER(J26),I26>0),MAX(0,(I26*J26+SUMPRODUCT((Закрытые!$B$5:$B$300=$B26)*((Закрытые!$F$5:$F$300+Закрытые!$I$5:$I$300-ABS(Закрытые!$F$5:$F$300-Закрытые!$I$5:$I$300))/2)*(Закрытые!$J$5:$J$300-Закрытые!$G$5:$G$300)))/I26)/(1+N(Ввод!$E$17)/100),""))
H27: =IF(AND(ISNUMBER(F27),ISNUMBER(G27)),F27*G27,"") | K27: =IF(AND(ISNUMBER(I27),ISNUMBER(J27)),I27*J27,"") | L27: =IF(COUNT(F27,I27)=0,"",N(F27)-N(I27)) | M27: =IF(COUNT(H27,K27)=0,"",N(K27)-N(H27)) | N27: =IF(AND(ISNUMBER(F27),ISNUMBER(G27),F27>0,1-N(Ввод!$E$17)/100>0),MAX(0,(F27*G27-SUMPRODUCT((Закрытые!$B$5:$B$300=$B27)*((Закрытые!$F$5:$F$300+Закрытые!$I$5:$I$300-ABS(Закрытые!$F$5:$F$300-Закрытые!$I$5:$I$300))/2)*(Закрытые!$J$5:$J$300-Закрытые!$G$5:$G$300)))/F27)/(1-N(Ввод!$E$17)/100),IF(AND(ISNUMBER(I27),ISNUMBER(J27),I27>0),MAX(0,(I27*J27+SUMPRODUCT((Закрытые!$B$5:$B$300=$B27)*((Закрытые!$F$5:$F$300+Закрытые!$I$5:$I$300-ABS(Закрытые!$F$5:$F$300-Закрытые!$I$5:$I$300))/2)*(Закрытые!$J$5:$J$300-Закрытые!$G$5:$G$300)))/I27)/(1+N(Ввод!$E$17)/100),""))
H28: =IF(AND(ISNUMBER(F28),ISNUMBER(G28)),F28*G28,"") | K28: =IF(AND(ISNUMBER(I28),ISNUMBER(J28)),I28*J28,"") | L28: =IF(COUNT(F28,I28)=0,"",N(F28)-N(I28)) | M28: =IF(COUNT(H28,K28)=0,"",N(K28)-N(H28)) | N28: =IF(AND(ISNUMBER(F28),ISNUMBER(G28),F28>0,1-N(Ввод!$E$17)/100>0),MAX(0,(F28*G28-SUMPRODUCT((Закрытые!$B$5:$B$300=$B28)*((Закрытые!$F$5:$F$300+Закрытые!$I$5:$I$300-ABS(Закрытые!$F$5:$F$300-Закрытые!$I$5:$I$300))/2)*(Закрытые!$J$5:$J$300-Закрытые!$G$5:$G$300)))/F28)/(1-N(Ввод!$E$17)/100),IF(AND(ISNUMBER(I28),ISNUMBER(J28),I28>0),MAX(0,(I28*J28+SUMPRODUCT((Закрытые!$B$5:$B$300=$B28)*((Закрытые!$F$5:$F$300+Закрытые!$I$5:$I$300-ABS(Закрытые!$F$5:$F$300-Закрытые!$I$5:$I$300))/2)*(Закрытые!$J$5:$J$300-Закрытые!$G$5:$G$300)))/I28)/(1+N(Ввод!$E$17)/100),""))
H29: =IF(AND(ISNUMBER(F29),ISNUMBER(G29)),F29*G29,"") | K29: =IF(AND(ISNUMBER(I29),ISNUMBER(J29)),I29*J29,"") | L29: =IF(COUNT(F29,I29)=0,"",N(F29)-N(I29)) | M29: =IF(COUNT(H29,K29)=0,"",N(K29)-N(H29)) | N29: =IF(AND(ISNUMBER(F29),ISNUMBER(G29),F29>0,1-N(Ввод!$E$17)/100>0),MAX(0,(F29*G29-SUMPRODUCT((Закрытые!$B$5:$B$300=$B29)*((Закрытые!$F$5:$F$300+Закрытые!$I$5:$I$300-ABS(Закрытые!$F$5:$F$300-Закрытые!$I$5:$I$300))/2)*(Закрытые!$J$5:$J$300-Закрытые!$G$5:$G$300)))/F29)/(1-N(Ввод!$E$17)/100),IF(AND(ISNUMBER(I29),ISNUMBER(J29),I29>0),MAX(0,(I29*J29+SUMPRODUCT((Закрытые!$B$5:$B$300=$B29)*((Закрытые!$F$5:$F$300+Закрытые!$I$5:$I$300-ABS(Закрытые!$F$5:$F$300-Закрытые!$I$5:$I$300))/2)*(Закрытые!$J$5:$J$300-Закрытые!$G$5:$G$300)))/I29)/(1+N(Ввод!$E$17)/100),""))
H30: =IF(AND(ISNUMBER(F30),ISNUMBER(G30)),F30*G30,"") | K30: =IF(AND(ISNUMBER(I30),ISNUMBER(J30)),I30*J30,"") | L30: =IF(COUNT(F30,I30)=0,"",N(F30)-N(I30)) | M30: =IF(COUNT(H30,K30)=0,"",N(K30)-N(H30)) | N30: =IF(AND(ISNUMBER(F30),ISNUMBER(G30),F30>0,1-N(Ввод!$E$17)/100>0),MAX(0,(F30*G30-SUMPRODUCT((Закрытые!$B$5:$B$300=$B30)*((Закрытые!$F$5:$F$300+Закрытые!$I$5:$I$300-ABS(Закрытые!$F$5:$F$300-Закрытые!$I$5:$I$300))/2)*(Закрытые!$J$5:$J$300-Закрытые!$G$5:$G$300)))/F30)/(1-N(Ввод!$E$17)/100),IF(AND(ISNUMBER(I30),ISNUMBER(J30),I30>0),MAX(0,(I30*J30+SUMPRODUCT((Закрытые!$B$5:$B$300=$B30)*((Закрытые!$F$5:$F$300+Закрытые!$I$5:$I$300-ABS(Закрытые!$F$5:$F$300-Закрытые!$I$5:$I$300))/2)*(Закрытые!$J$5:$J$300-Закрытые!$G$5:$G$300)))/I30)/(1+N(Ввод!$E$17)/100),""))
H31: =IF(AND(ISNUMBER(F31),ISNUMBER(G31)),F31*G31,"") | K31: =IF(AND(ISNUMBER(I31),ISNUMBER(J31)),I31*J31,"") | L31: =IF(COUNT(F31,I31)=0,"",N(F31)-N(I31)) | M31: =IF(COUNT(H31,K31)=0,"",N(K31)-N(H31)) | N31: =IF(AND(ISNUMBER(F31),ISNUMBER(G31),F31>0,1-N(Ввод!$E$17)/100>0),MAX(0,(F31*G31-SUMPRODUCT((Закрытые!$B$5:$B$300=$B31)*((Закрытые!$F$5:$F$300+Закрытые!$I$5:$I$300-ABS(Закрытые!$F$5:$F$300-Закрытые!$I$5:$I$300))/2)*(Закрытые!$J$5:$J$300-Закрытые!$G$5:$G$300)))/F31)/(1-N(Ввод!$E$17)/100),IF(AND(ISNUMBER(I31),ISNUMBER(J31),I31>0),MAX(0,(I31*J31+SUMPRODUCT((Закрытые!$B$5:$B$300=$B31)*((Закрытые!$F$5:$F$300+Закрытые!$I$5:$I$300-ABS(Закрытые!$F$5:$F$300-Закрытые!$I$5:$I$300))/2)*(Закрытые!$J$5:$J$300-Закрытые!$G$5:$G$300)))/I31)/(1+N(Ввод!$E$17)/100),""))
H32: =IF(AND(ISNUMBER(F32),ISNUMBER(G32)),F32*G32,"") | K32: =IF(AND(ISNUMBER(I32),ISNUMBER(J32)),I32*J32,"") | L32: =IF(COUNT(F32,I32)=0,"",N(F32)-N(I32)) | M32: =IF(COUNT(H32,K32)=0,"",N(K32)-N(H32)) | N32: =IF(AND(ISNUMBER(F32),ISNUMBER(G32),F32>0,1-N(Ввод!$E$17)/100>0),MAX(0,(F32*G32-SUMPRODUCT((Закрытые!$B$5:$B$300=$B32)*((Закрытые!$F$5:$F$300+Закрытые!$I$5:$I$300-ABS(Закрытые!$F$5:$F$300-Закрытые!$I$5:$I$300))/2)*(Закрытые!$J$5:$J$300-Закрытые!$G$5:$G$300)))/F32)/(1-N(Ввод!$E$17)/100),IF(AND(ISNUMBER(I32),ISNUMBER(J32),I32>0),MAX(0,(I32*J32+SUMPRODUCT((Закрытые!$B$5:$B$300=$B32)*((Закрытые!$F$5:$F$300+Закрытые!$I$5:$I$300-ABS(Закрытые!$F$5:$F$300-Закрытые!$I$5:$I$300))/2)*(Закрытые!$J$5:$J$300-Закрытые!$G$5:$G$300)))/I32)/(1+N(Ввод!$E$17)/100),""))
H33: =IF(AND(ISNUMBER(F33),ISNUMBER(G33)),F33*G33,"") | K33: =IF(AND(ISNUMBER(I33),ISNUMBER(J33)),I33*J33,"") | L33: =IF(COUNT(F33,I33)=0,"",N(F33)-N(I33)) | M33: =IF(COUNT(H33,K33)=0,"",N(K33)-N(H33)) | N33: =IF(AND(ISNUMBER(F33),ISNUMBER(G33),F33>0,1-N(Ввод!$E$17)/100>0),MAX(0,(F33*G33-SUMPRODUCT((Закрытые!$B$5:$B$300=$B33)*((Закрытые!$F$5:$F$300+Закрытые!$I$5:$I$300-ABS(Закрытые!$F$5:$F$300-Закрытые!$I$5:$I$300))/2)*(Закрытые!$J$5:$J$300-Закрытые!$G$5:$G$300)))/F33)/(1-N(Ввод!$E$17)/100),IF(AND(ISNUMBER(I33),ISNUMBER(J33),I33>0),MAX(0,(I33*J33+SUMPRODUCT((Закрытые!$B$5:$B$300=$B33)*((Закрытые!$F$5:$F$300+Закрытые!$I$5:$I$300-ABS(Закрытые!$F$5:$F$300-Закрытые!$I$5:$I$300))/2)*(Закрытые!$J$5:$J$300-Закрытые!$G$5:$G$300)))/I33)/(1+N(Ввод!$E$17)/100),""))
H34: =IF(AND(ISNUMBER(F34),ISNUMBER(G34)),F34*G34,"") | K34: =IF(AND(ISNUMBER(I34),ISNUMBER(J34)),I34*J34,"") | L34: =IF(COUNT(F34,I34)=0,"",N(F34)-N(I34)) | M34: =IF(COUNT(H34,K34)=0,"",N(K34)-N(H34)) | N34: =IF(AND(ISNUMBER(F34),ISNUMBER(G34),F34>0,1-N(Ввод!$E$17)/100>0),MAX(0,(F34*G34-SUMPRODUCT((Закрытые!$B$5:$B$300=$B34)*((Закрытые!$F$5:$F$300+Закрытые!$I$5:$I$300-ABS(Закрытые!$F$5:$F$300-Закрытые!$I$5:$I$300))/2)*(Закрытые!$J$5:$J$300-Закрытые!$G$5:$G$300)))/F34)/(1-N(Ввод!$E$17)/100),IF(AND(ISNUMBER(I34),ISNUMBER(J34),I34>0),MAX(0,(I34*J34+SUMPRODUCT((Закрытые!$B$5:$B$300=$B34)*((Закрытые!$F$5:$F$300+Закрытые!$I$5:$I$300-ABS(Закрытые!$F$5:$F$300-Закрытые!$I$5:$I$300))/2)*(Закрытые!$J$5:$J$300-Закрытые!$G$5:$G$300)))/I34)/(1+N(Ввод!$E$17)/100),""))
H35: =IF(AND(ISNUMBER(F35),ISNUMBER(G35)),F35*G35,"") | K35: =IF(AND(ISNUMBER(I35),ISNUMBER(J35)),I35*J35,"") | L35: =IF(COUNT(F35,I35)=0,"",N(F35)-N(I35)) | M35: =IF(COUNT(H35,K35)=0,"",N(K35)-N(H35)) | N35: =IF(AND(ISNUMBER(F35),ISNUMBER(G35),F35>0,1-N(Ввод!$E$17)/100>0),MAX(0,(F35*G35-SUMPRODUCT((Закрытые!$B$5:$B$300=$B35)*((Закрытые!$F$5:$F$300+Закрытые!$I$5:$I$300-ABS(Закрытые!$F$5:$F$300-Закрытые!$I$5:$I$300))/2)*(Закрытые!$J$5:$J$300-Закрытые!$G$5:$G$300)))/F35)/(1-N(Ввод!$E$17)/100),IF(AND(ISNUMBER(I35),ISNUMBER(J35),I35>0),MAX(0,(I35*J35+SUMPRODUCT((Закрытые!$B$5:$B$300=$B35)*((Закрытые!$F$5:$F$300+Закрытые!$I$5:$I$300-ABS(Закрытые!$F$5:$F$300-Закрытые!$I$5:$I$300))/2)*(Закрытые!$J$5:$J$300-Закрытые!$G$5:$G$300)))/I35)/(1+N(Ввод!$E$17)/100),""))
H36: =IF(AND(ISNUMBER(F36),ISNUMBER(G36)),F36*G36,"") | K36: =IF(AND(ISNUMBER(I36),ISNUMBER(J36)),I36*J36,"") | L36: =IF(COUNT(F36,I36)=0,"",N(F36)-N(I36)) | M36: =IF(COUNT(H36,K36)=0,"",N(K36)-N(H36)) | N36: =IF(AND(ISNUMBER(F36),ISNUMBER(G36),F36>0,1-N(Ввод!$E$17)/100>0),MAX(0,(F36*G36-SUMPRODUCT((Закрытые!$B$5:$B$300=$B36)*((Закрытые!$F$5:$F$300+Закрытые!$I$5:$I$300-ABS(Закрытые!$F$5:$F$300-Закрытые!$I$5:$I$300))/2)*(Закрытые!$J$5:$J$300-Закрытые!$G$5:$G$300)))/F36)/(1-N(Ввод!$E$17)/100),IF(AND(ISNUMBER(I36),ISNUMBER(J36),I36>0),MAX(0,(I36*J36+SUMPRODUCT((Закрытые!$B$5:$B$300=$B36)*((Закрытые!$F$5:$F$300+Закрытые!$I$5:$I$300-ABS(Закрытые!$F$5:$F$300-Закрытые!$I$5:$I$300))/2)*(Закрытые!$J$5:$J$300-Закрытые!$G$5:$G$300)))/I36)/(1+N(Ввод!$E$17)/100),""))
H37: =IF(AND(ISNUMBER(F37),ISNUMBER(G37)),F37*G37,"") | K37: =IF(AND(ISNUMBER(I37),ISNUMBER(J37)),I37*J37,"") | L37: =IF(COUNT(F37,I37)=0,"",N(F37)-N(I37)) | M37: =IF(COUNT(H37,K37)=0,"",N(K37)-N(H37)) | N37: =IF(AND(ISNUMBER(F37),ISNUMBER(G37),F37>0,1-N(Ввод!$E$17)/100>0),MAX(0,(F37*G37-SUMPRODUCT((Закрытые!$B$5:$B$300=$B37)*((Закрытые!$F$5:$F$300+Закрытые!$I$5:$I$300-ABS(Закрытые!$F$5:$F$300-Закрытые!$I$5:$I$300))/2)*(Закрытые!$J$5:$J$300-Закрытые!$G$5:$G$300)))/F37)/(1-N(Ввод!$E$17)/100),IF(AND(ISNUMBER(I37),ISNUMBER(J37),I37>0),MAX(0,(I37*J37+SUMPRODUCT((Закрытые!$B$5:$B$300=$B37)*((Закрытые!$F$5:$F$300+Закрытые!$I$5:$I$300-ABS(Закрытые!$F$5:$F$300-Закрытые!$I$5:$I$300))/2)*(Закрытые!$J$5:$J$300-Закрытые!$G$5:$G$300)))/I37)/(1+N(Ввод!$E$17)/100),""))
... H300: =IF(AND(ISNUMBER(F300),ISNUMBER(G300)),F300*G300,"") | K300: =IF(AND(ISNUMBER(I300),ISNUMBER(J300)),I300*J300,"") | L300: =IF(COUNT(F300,I300)=0,"",N(F300)-N(I300)) | M300: =IF(COUNT(H300,K300)=0,"",N(K300)-N(H300)) | N300: =IF(AND(ISNUMBER(F300),ISNUMBER(G300),F300>0,1-N(Ввод!$E$17)/100>0),MAX(0,(F300*G300-SUMPRODUCT((Закрытые!$B$5:$B$300=$B300)*((Закрытые!$F$5:$F$300+Закрытые!$I$5:$I$300-ABS(Закрытые!$F$5:$F$300-Закрытые!$I$5:$I$300))/2)*(Закрытые!$J$5:$J$300-Закрытые!$G$5:$G$300)))/F300)/(1-N(Ввод!$E$17)/100),IF(AND(ISNUMBER(I300),ISNUMBER(J300),I300>0),MAX(0,(I300*J300+SUMPRODUCT((Закрытые!$B$5:$B$300=$B300)*((Закрытые!$F$5:$F$300+Закрытые!$I$5:$I$300-ABS(Закрытые!$F$5:$F$300-Закрытые!$I$5:$I$300))/2)*(Закрытые!$J$5:$J$300-Закрытые!$G$5:$G$300)))/I300)/(1+N(Ввод!$E$17)/100),""))

Sheet ИТОГО Торговля
B1: CRYPTO JOURNAL • ИТОГО ТОРГОВЛЯ
B4: Пара | C4: Покупка | D4: Курс | E4: Сумма | F4: Продажа | G4: Курс | H4: Сумма | I4: Дельта 1 | J4: Дельта 2 | K4: P&L | L4: P&L% | M4: Break even
B5: AAVE/ETH | C5: =IF(SUMIFS(Торговля!$F$5:$F$300,Торговля!$E$5:$E$300,$B5)+SUMIFS(Закрытые!$F$5:$F$300,Закрытые!$E$5:$E$300,$B5,Закрытые!$B$5:$B$300,"T-*")=0,"",SUMIFS(Торговля!$F$5:$F$300,Торговля!$E$5:$E$300,$B5)+SUMIFS(Закрытые!$F$5:$F$300,Закрытые!$E$5:$E$300,$B5,Закрытые!$B$5:$B$300,"T-*")) | D5: =IF(C5="","",(SUMPRODUCT((Торговля!$E$5:$E$300=$B5)*Торговля!$F$5:$F$300*Торговля!$G$5:$G$300)+SUMPRODUCT((Закрытые!$E$5:$E$300=$B5)*(LEFT(Закрытые!$B$5:$B$300,2)="T-")*Закрытые!$F$5:$F$300*Закрытые!$G$5:$G$300))/C5) | E5: =IF(C5="","",SUMIFS(Торговля!$H$5:$H$300,Торговля!$E$5:$E$300,$B5)+SUMIFS(Закрытые!$H$5:$H$300,Закрытые!$E$5:$E$300,$B5,Закрытые!$B$5:$B$300,"T-*")) | F5: =IF(SUMIFS(Торговля!$I$5:$I$300,Торговля!$E$5:$E$300,$B5)+SUMIFS(Закрытые!$I$5:$I$300,Закрытые!$E$5:$E$300,$B5,Закрытые!$B$5:$B$300,"T-*")=0,"",SUMIFS(Торговля!$I$5:$I$300,Торговля!$E$5:$E$300,$B5)+SUMIFS(Закрытые!$I$5:$I$300,Закрытые!$E$5:$E$300,$B5,Закрытые!$B$5:$B$300,"T-*")) | G5: =IF(F5="","",(SUMPRODUCT((Торговля!$E$5:$E$300=$B5)*Торговля!$I$5:$I$300*Торговля!$J$5:$J$300)+SUMPRODUCT((Закрытые!$E$5:$E$300=$B5)*(LEFT(Закрытые!$B$5:$B$300,2)="T-")*Закрытые!$I$5:$I$300*Закрытые!$J$5:$J$300))/F5) | H5: =IF(F5="","",SUMIFS(Торговля!$K$5:$K$300,Торговля!$E$5:$E$300,$B5)+SUMIFS(Закрытые!$K$5:$K$300,Закрытые!$E$5:$E$300,$B5,Закрытые!$B$5:$B$300,"T-*")) | I5: =IF($B5="","",IF(COUNTIFS(Торговля!$E$5:$E$300,$B5)+COUNTIFS(Закрытые!$E$5:$E$300,$B5,Закрытые!$B$5:$B$300,"T-*")=0,"",ROUND(SUMIFS(Торговля!$L$5:$L$300,Торговля!$E$5:$E$300,$B5)+SUMIFS(Закрытые!$L$5:$L$300,Закрытые!$E$5:$E$300,$B5,Закрытые!$B$5:$B$300,"T-*"),8))) | J5: =IF($B5="","",IF(COUNTIFS(Торговля!$E$5:$E$300,$B5)+COUNTIFS(Закрытые!$E$5:$E$300,$B5,Закрытые!$B$5:$B$300,"T-*")=0,"",ROUND(SUMIFS(Торговля!$M$5:$M$300,Торговля!$E$5:$E$300,$B5)+SUMIFS(Закрытые!$M$5:$M$300,Закрытые!$E$5:$E$300,$B5,Закрытые!$B$5:$B$300,"T-*"),8))) | K5: =IF($B5="","",ROUND(SUMIFS(Закрытые!$N$5:$N$300,Закрытые!$E$5:$E$300,$B5,Закрытые!$B$5:$B$300,"T-*"),8)) | L5: =IF(K5="","",IF(SUMPRODUCT((Закрытые!$E$5:$E$300=$B5)*(LEFT(Закрытые!$B$5:$B$300,2)="T-")*(COUNTIF(Торговля!$B$5:$B$300,Закрытые!$B$5:$B$300)=0)*((Закрытые!$F$5:$F$300+Закрытые!$I$5:$I$300-ABS(Закрытые!$F$5:$F$300-Закрытые!$I$5:$I$300))/2)*Закрытые!$G$5:$G$300)<=0,0,ROUND(K5/SUMPRODUCT((Закрытые!$E$5:$E$300=$B5)*(LEFT(Закрытые!$B$5:$B$300,2)="T-")*(COUNTIF(Торговля!$B$5:$B$300,Закрытые!$B$5:$B$300)=0)*((Закрытые!$F$5:$F$300+Закрытые!$I$5:$I$300-ABS(Закрытые!$F$5:$F$300-Закрытые!$I$5:$I$300))/2)*Закрытые!$G$5:$G$300)*100,2))) | M5: =IF(OR(ROUND(N(C5)-N(F5),8)=0,1-N(Ввод!$E$17)/100<=0),"",IF(N(C5)>N(F5),(N(E5)-N(H5))/((N(C5)-N(F5))*(1-N(Ввод!$E$17)/100)),(N(H5)-N(E5))/((N(F5)-N(C5))*(1+N(Ввод!$E$17)/100))))
B6: ADA/USDT | C6: =IF(SUMIFS(Торговля!$F$5:$F$300,Торговля!$E$5:$E$300,$B6)+SUMIFS(Закрытые!$F$5:$F$300,Закрытые!$E$5:$E$300,$B6,Закрытые!$B$5:$B$300,"T-*")=0,"",SUMIFS(Торговля!$F$5:$F$300,Торговля!$E$5:$E$300,$B6)+SUMIFS(Закрытые!$F$5:$F$300,Закрытые!$E$5:$E$300,$B6,Закрытые!$B$5:$B$300,"T-*")) | D6: =IF(C6="","",(SUMPRODUCT((Торговля!$E$5:$E$300=$B6)*Торговля!$F$5:$F$300*Торговля!$G$5:$G$300)+SUMPRODUCT((Закрытые!$E$5:$E$300=$B6)*(LEFT(Закрытые!$B$5:$B$300,2)="T-")*Закрытые!$F$5:$F$300*Закрытые!$G$5:$G$300))/C6) | E6: =IF(C6="","",SUMIFS(Торговля!$H$5:$H$300,Торговля!$E$5:$E$300,$B6)+SUMIFS(Закрытые!$H$5:$H$300,Закрытые!$E$5:$E$300,$B6,Закрытые!$B$5:$B$300,"T-*")) | F6: =IF(SUMIFS(Торговля!$I$5:$I$300,Торговля!$E$5:$E$300,$B6)+SUMIFS(Закрытые!$I$5:$I$300,Закрытые!$E$5:$E$300,$B6,Закрытые!$B$5:$B$300,"T-*")=0,"",SUMIFS(Торговля!$I$5:$I$300,Торговля!$E$5:$E$300,$B6)+SUMIFS(Закрытые!$I$5:$I$300,Закрытые!$E$5:$E$300,$B6,Закрытые!$B$5:$B$300,"T-*")) | G6: =IF(F6="","",(SUMPRODUCT((Торговля!$E$5:$E$300=$B6)*Торговля!$I$5:$I$300*Торговля!$J$5:$J$300)+SUMPRODUCT((Закрытые!$E$5:$E$300=$B6)*(LEFT(Закрытые!$B$5:$B$300,2)="T-")*Закрытые!$I$5:$I$300*Закрытые!$J$5:$J$300))/F6) | H6: =IF(F6="","",SUMIFS(Торговля!$K$5:$K$300,Торговля!$E$5:$E$300,$B6)+SUMIFS(Закрытые!$K$5:$K$300,Закрытые!$E$5:$E$300,$B6,Закрытые!$B$5:$B$300,"T-*")) | I6: =IF($B6="","",IF(COUNTIFS(Торговля!$E$5:$E$300,$B6)+COUNTIFS(Закрытые!$E$5:$E$300,$B6,Закрытые!$B$5:$B$300,"T-*")=0,"",ROUND(SUMIFS(Торговля!$L$5:$L$300,Торговля!$E$5:$E$300,$B6)+SUMIFS(Закрытые!$L$5:$L$300,Закрытые!$E$5:$E$300,$B6,Закрытые!$B$5:$B$300,"T-*"),8))) | J6: =IF($B6="","",IF(COUNTIFS(Торговля!$E$5:$E$300,$B6)+COUNTIFS(Закрытые!$E$5:$E$300,$B6,Закрытые!$B$5:$B$300,"T-*")=0,"",ROUND(SUMIFS(Торговля!$M$5:$M$300,Торговля!$E$5:$E$300,$B6)+SUMIFS(Закрытые!$M$5:$M$300,Закрытые!$E$5:$E$300,$B6,Закрытые!$B$5:$B$300,"T-*"),8))) | K6: =IF($B6="","",ROUND(SUMIFS(Закрытые!$N$5:$N$300,Закрытые!$E$5:$E$300,$B6,Закрытые!$B$5:$B$300,"T-*"),8)) | L6: =IF(K6="","",IF(SUMPRODUCT((Закрытые!$E$5:$E$300=$B6)*(LEFT(Закрытые!$B$5:$B$300,2)="T-")*(COUNTIF(Торговля!$B$5:$B$300,Закрытые!$B$5:$B$300)=0)*((Закрытые!$F$5:$F$300+Закрытые!$I$5:$I$300-ABS(Закрытые!$F$5:$F$300-Закрытые!$I$5:$I$300))/2)*Закрытые!$G$5:$G$300)<=0,0,ROUND(K6/SUMPRODUCT((Закрытые!$E$5:$E$300=$B6)*(LEFT(Закрытые!$B$5:$B$300,2)="T-")*(COUNTIF(Торговля!$B$5:$B$300,Закрытые!$B$5:$B$300)=0)*((Закрытые!$F$5:$F$300+Закрытые!$I$5:$I$300-ABS(Закрытые!$F$5:$F$300-Закрытые!$I$5:$I$300))/2)*Закрытые!$G$5:$G$300)*100,2))) | M6: =IF(OR(ROUND(N(C6)-N(F6),8)=0,1-N(Ввод!$E$17)/100<=0),"",IF(N(C6)>N(F6),(N(E6)-N(H6))/((N(C6)-N(F6))*(1-N(Ввод!$E$17)/100)),(N(H6)-N(E6))/((N(F6)-N(C6))*(1+N(Ввод!$E$17)/100))))
B7: BNB/BTC | C7: =IF(SUMIFS(Торговля!$F$5:$F$300,Торговля!$E$5:$E$300,$B7)+SUMIFS(Закрытые!$F$5:$F$300,Закрытые!$E$5:$E$300,$B7,Закрытые!$B$5:$B$300,"T-*")=0,"",SUMIFS(Торговля!$F$5:$F$300,Торговля!$E$5:$E$300,$B7)+SUMIFS(Закрытые!$F$5:$F$300,Закрытые!$E$5:$E$300,$B7,Закрытые!$B$5:$B$300,"T-*")) | D7: =IF(C7="","",(SUMPRODUCT((Торговля!$E$5:$E$300=$B7)*Торговля!$F$5:$F$300*Торговля!$G$5:$G$300)+SUMPRODUCT((Закрытые!$E$5:$E$300=$B7)*(LEFT(Закрытые!$B$5:$B$300,2)="T-")*Закрытые!$F$5:$F$300*Закрытые!$G$5:$G$300))/C7) | E7: =IF(C7="","",SUMIFS(Торговля!$H$5:$H$300,Торговля!$E$5:$E$300,$B7)+SUMIFS(Закрытые!$H$5:$H$300,Закрытые!$E$5:$E$300,$B7,Закрытые!$B$5:$B$300,"T-*")) | F7: =IF(SUMIFS(Торговля!$I$5:$I$300,Торговля!$E$5:$E$300,$B7)+SUMIFS(Закрытые!$I$5:$I$300,Закрытые!$E$5:$E$300,$B7,Закрытые!$B$5:$B$300,"T-*")=0,"",SUMIFS(Торговля!$I$5:$I$300,Торговля!$E$5:$E$300,$B7)+SUMIFS(Закрытые!$I$5:$I$300,Закрытые!$E$5:$E$300,$B7,Закрытые!$B$5:$B$300,"T-*")) | G7: =IF(F7="","",(SUMPRODUCT((Торговля!$E$5:$E$300=$B7)*Торговля!$I$5:$I$300*Торговля!$J$5:$J$300)+SUMPRODUCT((Закрытые!$E$5:$E$300=$B7)*(LEFT(Закрытые!$B$5:$B$300,2)="T-")*Закрытые!$I$5:$I$300*Закрытые!$J$5:$J$300))/F7) | H7: =IF(F7="","",SUMIFS(Торговля!$K$5:$K$300,Торговля!$E$5:$E$300,$B7)+SUMIFS(Закрытые!$K$5:$K$300,Закрытые!$E$5:$E$300,$B7,Закрытые!$B$5:$B$300,"T-*")) | I7: =IF($B7="","",IF(COUNTIFS(Торговля!$E$5:$E$300,$B7)+COUNTIFS(Закрытые!$E$5:$E$300,$B7,Закрытые!$B$5:$B$300,"T-*")=0,"",ROUND(SUMIFS(Торговля!$L$5:$L$300,Торговля!$E$5:$E$300,$B7)+SUMIFS(Закрытые!$L$5:$L$300,Закрытые!$E$5:$E$300,$B7,Закрытые!$B$5:$B$300,"T-*"),8))) | J7: =IF($B7="","",IF(COUNTIFS(Торговля!$E$5:$E$300,$B7)+COUNTIFS(Закрытые!$E$5:$E$300,$B7,Закрытые!$B$5:$B$300,"T-*")=0,"",ROUND(SUMIFS(Торговля!$M$5:$M$300,Торговля!$E$5:$E$300,$B7)+SUMIFS(Закрытые!$M$5:$M$300,Закрытые!$E$5:$E$300,$B7,Закрытые!$B$5:$B$300,"T-*"),8))) | K7: =IF($B7="","",ROUND(SUMIFS(Закрытые!$N$5:$N$300,Закрытые!$E$5:$E$300,$B7,Закрытые!$B$5:$B$300,"T-*"),8)) | L7: =IF(K7="","",IF(SUMPRODUCT((Закрытые!$E$5:$E$300=$B7)*(LEFT(Закрытые!$B$5:$B$300,2)="T-")*(COUNTIF(Торговля!$B$5:$B$300,Закрытые!$B$5:$B$300)=0)*((Закрытые!$F$5:$F$300+Закрытые!$I$5:$I$300-ABS(Закрытые!$F$5:$F$300-Закрытые!$I$5:$I$300))/2)*Закрытые!$G$5:$G$300)<=0,0,ROUND(K7/SUMPRODUCT((Закрытые!$E$5:$E$300=$B7)*(LEFT(Закрытые!$B$5:$B$300,2)="T-")*(COUNTIF(Торговля!$B$5:$B$300,Закрытые!$B$5:$B$300)=0)*((Закрытые!$F$5:$F$300+Закрытые!$I$5:$I$300-ABS(Закрытые!$F$5:$F$300-Закрытые!$I$5:$I$300))/2)*Закрытые!$G$5:$G$300)*100,2))) | M7: =IF(OR(ROUND(N(C7)-N(F7),8)=0,1-N(Ввод!$E$17)/100<=0),"",IF(N(C7)>N(F7),(N(E7)-N(H7))/((N(C7)-N(F7))*(1-N(Ввод!$E$17)/100)),(N(H7)-N(E7))/((N(F7)-N(C7))*(1+N(Ввод!$E$17)/100))))
B8: BNB/ETH | C8: =IF(SUMIFS(Торговля!$F$5:$F$300,Торговля!$E$5:$E$300,$B8)+SUMIFS(Закрытые!$F$5:$F$300,Закрытые!$E$5:$E$300,$B8,Закрытые!$B$5:$B$300,"T-*")=0,"",SUMIFS(Торговля!$F$5:$F$300,Торговля!$E$5:$E$300,$B8)+SUMIFS(Закрытые!$F$5:$F$300,Закрытые!$E$5:$E$300,$B8,Закрытые!$B$5:$B$300,"T-*")) | D8: =IF(C8="","",(SUMPRODUCT((Торговля!$E$5:$E$300=$B8)*Торговля!$F$5:$F$300*Торговля!$G$5:$G$300)+SUMPRODUCT((Закрытые!$E$5:$E$300=$B8)*(LEFT(Закрытые!$B$5:$B$300,2)="T-")*Закрытые!$F$5:$F$300*Закрытые!$G$5:$G$300))/C8) | E8: =IF(C8="","",SUMIFS(Торговля!$H$5:$H$300,Торговля!$E$5:$E$300,$B8)+SUMIFS(Закрытые!$H$5:$H$300,Закрытые!$E$5:$E$300,$B8,Закрытые!$B$5:$B$300,"T-*")) | F8: =IF(SUMIFS(Торговля!$I$5:$I$300,Торговля!$E$5:$E$300,$B8)+SUMIFS(Закрытые!$I$5:$I$300,Закрытые!$E$5:$E$300,$B8,Закрытые!$B$5:$B$300,"T-*")=0,"",SUMIFS(Торговля!$I$5:$I$300,Торговля!$E$5:$E$300,$B8)+SUMIFS(Закрытые!$I$5:$I$300,Закрытые!$E$5:$E$300,$B8,Закрытые!$B$5:$B$300,"T-*")) | G8: =IF(F8="","",(SUMPRODUCT((Торговля!$E$5:$E$300=$B8)*Торговля!$I$5:$I$300*Торговля!$J$5:$J$300)+SUMPRODUCT((Закрытые!$E$5:$E$300=$B8)*(LEFT(Закрытые!$B$5:$B$300,2)="T-")*Закрытые!$I$5:$I$300*Закрытые!$J$5:$J$300))/F8) | H8: =IF(F8="","",SUMIFS(Торговля!$K$5:$K$300,Торговля!$E$5:$E$300,$B8)+SUMIFS(Закрытые!$K$5:$K$300,Закрытые!$E$5:$E$300,$B8,Закрытые!$B$5:$B$300,"T-*")) | I8: =IF($B8="","",IF(COUNTIFS(Торговля!$E$5:$E$300,$B8)+COUNTIFS(Закрытые!$E$5:$E$300,$B8,Закрытые!$B$5:$B$300,"T-*")=0,"",ROUND(SUMIFS(Торговля!$L$5:$L$300,Торговля!$E$5:$E$300,$B8)+SUMIFS(Закрытые!$L$5:$L$300,Закрытые!$E$5:$E$300,$B8,Закрытые!$B$5:$B$300,"T-*"),8))) | J8: =IF($B8="","",IF(COUNTIFS(Торговля!$E$5:$E$300,$B8)+COUNTIFS(Закрытые!$E$5:$E$300,$B8,Закрытые!$B$5:$B$300,"T-*")=0,"",ROUND(SUMIFS(Торговля!$M$5:$M$300,Торговля!$E$5:$E$300,$B8)+SUMIFS(Закрытые!$M$5:$M$300,Закрытые!$E$5:$E$300,$B8,Закрытые!$B$5:$B$300,"T-*"),8))) | K8: =IF($B8="","",ROUND(SUMIFS(Закрытые!$N$5:$N$300,Закрытые!$E$5:$E$300,$B8,Закрытые!$B$5:$B$300,"T-*"),8)) | L8: =IF(K8="","",IF(SUMPRODUCT((Закрытые!$E$5:$E$300=$B8)*(LEFT(Закрытые!$B$5:$B$300,2)="T-")*(COUNTIF(Торговля!$B$5:$B$300,Закрытые!$B$5:$B$300)=0)*((Закрытые!$F$5:$F$300+Закрытые!$I$5:$I$300-ABS(Закрытые!$F$5:$F$300-Закрытые!$I$5:$I$300))/2)*Закрытые!$G$5:$G$300)<=0,0,ROUND(K8/SUMPRODUCT((Закрытые!$E$5:$E$300=$B8)*(LEFT(Закрытые!$B$5:$B$300,2)="T-")*(COUNTIF(Торговля!$B$5:$B$300,Закрытые!$B$5:$B$300)=0)*((Закрытые!$F$5:$F$300+Закрытые!$I$5:$I$300-ABS(Закрытые!$F$5:$F$300-Закрытые!$I$5:$I$300))/2)*Закрытые!$G$5:$G$300)*100,2))) | M8: =IF(OR(ROUND(N(C8)-N(F8),8)=0,1-N(Ввод!$E$17)/100<=0),"",IF(N(C8)>N(F8),(N(E8)-N(H8))/((N(C8)-N(F8))*(1-N(Ввод!$E$17)/100)),(N(H8)-N(E8))/((N(F8)-N(C8))*(1+N(Ввод!$E$17)/100))))
B9: BNB/USDT | C9: =IF(SUMIFS(Торговля!$F$5:$F$300,Торговля!$E$5:$E$300,$B9)+SUMIFS(Закрытые!$F$5:$F$300,Закрытые!$E$5:$E$300,$B9,Закрытые!$B$5:$B$300,"T-*")=0,"",SUMIFS(Торговля!$F$5:$F$300,Торговля!$E$5:$E$300,$B9)+SUMIFS(Закрытые!$F$5:$F$300,Закрытые!$E$5:$E$300,$B9,Закрытые!$B$5:$B$300,"T-*")) | D9: =IF(C9="","",(SUMPRODUCT((Торговля!$E$5:$E$300=$B9)*Торговля!$F$5:$F$300*Торговля!$G$5:$G$300)+SUMPRODUCT((Закрытые!$E$5:$E$300=$B9)*(LEFT(Закрытые!$B$5:$B$300,2)="T-")*Закрытые!$F$5:$F$300*Закрытые!$G$5:$G$300))/C9) | E9: =IF(C9="","",SUMIFS(Торговля!$H$5:$H$300,Торговля!$E$5:$E$300,$B9)+SUMIFS(Закрытые!$H$5:$H$300,Закрытые!$E$5:$E$300,$B9,Закрытые!$B$5:$B$300,"T-*")) | F9: =IF(SUMIFS(Торговля!$I$5:$I$300,Торговля!$E$5:$E$300,$B9)+SUMIFS(Закрытые!$I$5:$I$300,Закрытые!$E$5:$E$300,$B9,Закрытые!$B$5:$B$300,"T-*")=0,"",SUMIFS(Торговля!$I$5:$I$300,Торговля!$E$5:$E$300,$B9)+SUMIFS(Закрытые!$I$5:$I$300,Закрытые!$E$5:$E$300,$B9,Закрытые!$B$5:$B$300,"T-*")) | G9: =IF(F9="","",(SUMPRODUCT((Торговля!$E$5:$E$300=$B9)*Торговля!$I$5:$I$300*Торговля!$J$5:$J$300)+SUMPRODUCT((Закрытые!$E$5:$E$300=$B9)*(LEFT(Закрытые!$B$5:$B$300,2)="T-")*Закрытые!$I$5:$I$300*Закрытые!$J$5:$J$300))/F9) | H9: =IF(F9="","",SUMIFS(Торговля!$K$5:$K$300,Торговля!$E$5:$E$300,$B9)+SUMIFS(Закрытые!$K$5:$K$300,Закрытые!$E$5:$E$300,$B9,Закрытые!$B$5:$B$300,"T-*")) | I9: =IF($B9="","",IF(COUNTIFS(Торговля!$E$5:$E$300,$B9)+COUNTIFS(Закрытые!$E$5:$E$300,$B9,Закрытые!$B$5:$B$300,"T-*")=0,"",ROUND(SUMIFS(Торговля!$L$5:$L$300,Торговля!$E$5:$E$300,$B9)+SUMIFS(Закрытые!$L$5:$L$300,Закрытые!$E$5:$E$300,$B9,Закрытые!$B$5:$B$300,"T-*"),8))) | J9: =IF($B9="","",IF(COUNTIFS(Торговля!$E$5:$E$300,$B9)+COUNTIFS(Закрытые!$E$5:$E$300,$B9,Закрытые!$B$5:$B$300,"T-*")=0,"",ROUND(SUMIFS(Торговля!$M$5:$M$300,Торговля!$E$5:$E$300,$B9)+SUMIFS(Закрытые!$M$5:$M$300,Закрытые!$E$5:$E$300,$B9,Закрытые!$B$5:$B$300,"T-*"),8))) | K9: =IF($B9="","",ROUND(SUMIFS(Закрытые!$N$5:$N$300,Закрытые!$E$5:$E$300,$B9,Закрытые!$B$5:$B$300,"T-*"),8)) | L9: =IF(K9="","",IF(SUMPRODUCT((Закрытые!$E$5:$E$300=$B9)*(LEFT(Закрытые!$B$5:$B$300,2)="T-")*(COUNTIF(Торговля!$B$5:$B$300,Закрытые!$B$5:$B$300)=0)*((Закрытые!$F$5:$F$300+Закрытые!$I$5:$I$300-ABS(Закрытые!$F$5:$F$300-Закрытые!$I$5:$I$300))/2)*Закрытые!$G$5:$G$300)<=0,0,ROUND(K9/SUMPRODUCT((Закрытые!$E$5:$E$300=$B9)*(LEFT(Закрытые!$B$5:$B$300,2)="T-")*(COUNTIF(Торговля!$B$5:$B$300,Закрытые!$B$5:$B$300)=0)*((Закрытые!$F$5:$F$300+Закрытые!$I$5:$I$300-ABS(Закрытые!$F$5:$F$300-Закрытые!$I$5:$I$300))/2)*Закрытые!$G$5:$G$300)*100,2))) | M9: =IF(OR(ROUND(N(C9)-N(F9),8)=0,1-N(Ввод!$E$17)/100<=0),"",IF(N(C9)>N(F9),(N(E9)-N(H9))/((N(C9)-N(F9))*(1-N(Ввод!$E$17)/100)),(N(H9)-N(E9))/((N(F9)-N(C9))*(1+N(Ввод!$E$17)/100))))
B10: BTC/USDT | C10: =IF(SUMIFS(Торговля!$F$5:$F$300,Торговля!$E$5:$E$300,$B10)+SUMIFS(Закрытые!$F$5:$F$300,Закрытые!$E$5:$E$300,$B10,Закрытые!$B$5:$B$300,"T-*")=0,"",SUMIFS(Торговля!$F$5:$F$300,Торговля!$E$5:$E$300,$B10)+SUMIFS(Закрытые!$F$5:$F$300,Закрытые!$E$5:$E$300,$B10,Закрытые!$B$5:$B$300,"T-*")) | D10: =IF(C10="","",(SUMPRODUCT((Торговля!$E$5:$E$300=$B10)*Торговля!$F$5:$F$300*Торговля!$G$5:$G$300)+SUMPRODUCT((Закрытые!$E$5:$E$300=$B10)*(LEFT(Закрытые!$B$5:$B$300,2)="T-")*Закрытые!$F$5:$F$300*Закрытые!$G$5:$G$300))/C10) | E10: =IF(C10="","",SUMIFS(Торговля!$H$5:$H$300,Торговля!$E$5:$E$300,$B10)+SUMIFS(Закрытые!$H$5:$H$300,Закрытые!$E$5:$E$300,$B10,Закрытые!$B$5:$B$300,"T-*")) | F10: =IF(SUMIFS(Торговля!$I$5:$I$300,Торговля!$E$5:$E$300,$B10)+SUMIFS(Закрытые!$I$5:$I$300,Закрытые!$E$5:$E$300,$B10,Закрытые!$B$5:$B$300,"T-*")=0,"",SUMIFS(Торговля!$I$5:$I$300,Торговля!$E$5:$E$300,$B10)+SUMIFS(Закрытые!$I$5:$I$300,Закрытые!$E$5:$E$300,$B10,Закрытые!$B$5:$B$300,"T-*")) | G10: =IF(F10="","",(SUMPRODUCT((Торговля!$E$5:$E$300=$B10)*Торговля!$I$5:$I$300*Торговля!$J$5:$J$300)+SUMPRODUCT((Закрытые!$E$5:$E$300=$B10)*(LEFT(Закрытые!$B$5:$B$300,2)="T-")*Закрытые!$I$5:$I$300*Закрытые!$J$5:$J$300))/F10) | H10: =IF(F10="","",SUMIFS(Торговля!$K$5:$K$300,Торговля!$E$5:$E$300,$B10)+SUMIFS(Закрытые!$K$5:$K$300,Закрытые!$E$5:$E$300,$B10,Закрытые!$B$5:$B$300,"T-*")) | I10: =IF($B10="","",IF(COUNTIFS(Торговля!$E$5:$E$300,$B10)+COUNTIFS(Закрытые!$E$5:$E$300,$B10,Закрытые!$B$5:$B$300,"T-*")=0,"",ROUND(SUMIFS(Торговля!$L$5:$L$300,Торговля!$E$5:$E$300,$B10)+SUMIFS(Закрытые!$L$5:$L$300,Закрытые!$E$5:$E$300,$B10,Закрытые!$B$5:$B$300,"T-*"),8))) | J10: =IF($B10="","",IF(COUNTIFS(Торговля!$E$5:$E$300,$B10)+COUNTIFS(Закрытые!$E$5:$E$300,$B10,Закрытые!$B$5:$B$300,"T-*")=0,"",ROUND(SUMIFS(Торговля!$M$5:$M$300,Торговля!$E$5:$E$300,$B10)+SUMIFS(Закрытые!$M$5:$M$300,Закрытые!$E$5:$E$300,$B10,Закрытые!$B$5:$B$300,"T-*"),8))) | K10: =IF($B10="","",ROUND(SUMIFS(Закрытые!$N$5:$N$300,Закрытые!$E$5:$E$300,$B10,Закрытые!$B$5:$B$300,"T-*"),8)) | L10: =IF(K10="","",IF(SUMPRODUCT((Закрытые!$E$5:$E$300=$B10)*(LEFT(Закрытые!$B$5:$B$300,2)="T-")*(COUNTIF(Торговля!$B$5:$B$300,Закрытые!$B$5:$B$300)=0)*((Закрытые!$F$5:$F$300+Закрытые!$I$5:$I$300-ABS(Закрытые!$F$5:$F$300-Закрытые!$I$5:$I$300))/2)*Закрытые!$G$5:$G$300)<=0,0,ROUND(K10/SUMPRODUCT((Закрытые!$E$5:$E$300=$B10)*(LEFT(Закрытые!$B$5:$B$300,2)="T-")*(COUNTIF(Торговля!$B$5:$B$300,Закрытые!$B$5:$B$300)=0)*((Закрытые!$F$5:$F$300+Закрытые!$I$5:$I$300-ABS(Закрытые!$F$5:$F$300-Закрытые!$I$5:$I$300))/2)*Закрытые!$G$5:$G$300)*100,2))) | M10: =IF(OR(ROUND(N(C10)-N(F10),8)=0,1-N(Ввод!$E$17)/100<=0),"",IF(N(C10)>N(F10),(N(E10)-N(H10))/((N(C10)-N(F10))*(1-N(Ввод!$E$17)/100)),(N(H10)-N(E10))/((N(F10)-N(C10))*(1+N(Ввод!$E$17)/100))))
B11: CAKE/ETH | C11: =IF(SUMIFS(Торговля!$F$5:$F$300,Торговля!$E$5:$E$300,$B11)+SUMIFS(Закрытые!$F$5:$F$300,Закрытые!$E$5:$E$300,$B11,Закрытые!$B$5:$B$300,"T-*")=0,"",SUMIFS(Торговля!$F$5:$F$300,Торговля!$E$5:$E$300,$B11)+SUMIFS(Закрытые!$F$5:$F$300,Закрытые!$E$5:$E$300,$B11,Закрытые!$B$5:$B$300,"T-*")) | D11: =IF(C11="","",(SUMPRODUCT((Торговля!$E$5:$E$300=$B11)*Торговля!$F$5:$F$300*Торговля!$G$5:$G$300)+SUMPRODUCT((Закрытые!$E$5:$E$300=$B11)*(LEFT(Закрытые!$B$5:$B$300,2)="T-")*Закрытые!$F$5:$F$300*Закрытые!$G$5:$G$300))/C11) | E11: =IF(C11="","",SUMIFS(Торговля!$H$5:$H$300,Торговля!$E$5:$E$300,$B11)+SUMIFS(Закрытые!$H$5:$H$300,Закрытые!$E$5:$E$300,$B11,Закрытые!$B$5:$B$300,"T-*")) | F11: =IF(SUMIFS(Торговля!$I$5:$I$300,Торговля!$E$5:$E$300,$B11)+SUMIFS(Закрытые!$I$5:$I$300,Закрытые!$E$5:$E$300,$B11,Закрытые!$B$5:$B$300,"T-*")=0,"",SUMIFS(Торговля!$I$5:$I$300,Торговля!$E$5:$E$300,$B11)+SUMIFS(Закрытые!$I$5:$I$300,Закрытые!$E$5:$E$300,$B11,Закрытые!$B$5:$B$300,"T-*")) | G11: =IF(F11="","",(SUMPRODUCT((Торговля!$E$5:$E$300=$B11)*Торговля!$I$5:$I$300*Торговля!$J$5:$J$300)+SUMPRODUCT((Закрытые!$E$5:$E$300=$B11)*(LEFT(Закрытые!$B$5:$B$300,2)="T-")*Закрытые!$I$5:$I$300*Закрытые!$J$5:$J$300))/F11) | H11: =IF(F11="","",SUMIFS(Торговля!$K$5:$K$300,Торговля!$E$5:$E$300,$B11)+SUMIFS(Закрытые!$K$5:$K$300,Закрытые!$E$5:$E$300,$B11,Закрытые!$B$5:$B$300,"T-*")) | I11: =IF($B11="","",IF(COUNTIFS(Торговля!$E$5:$E$300,$B11)+COUNTIFS(Закрытые!$E$5:$E$300,$B11,Закрытые!$B$5:$B$300,"T-*")=0,"",ROUND(SUMIFS(Торговля!$L$5:$L$300,Торговля!$E$5:$E$300,$B11)+SUMIFS(Закрытые!$L$5:$L$300,Закрытые!$E$5:$E$300,$B11,Закрытые!$B$5:$B$300,"T-*"),8))) | J11: =IF($B11="","",IF(COUNTIFS(Торговля!$E$5:$E$300,$B11)+COUNTIFS(Закрытые!$E$5:$E$300,$B11,Закрытые!$B$5:$B$300,"T-*")=0,"",ROUND(SUMIFS(Торговля!$M$5:$M$300,Торговля!$E$5:$E$300,$B11)+SUMIFS(Закрытые!$M$5:$M$300,Закрытые!$E$5:$E$300,$B11,Закрытые!$B$5:$B$300,"T-*"),8))) | K11: =IF($B11="","",ROUND(SUMIFS(Закрытые!$N$5:$N$300,Закрытые!$E$5:$E$300,$B11,Закрытые!$B$5:$B$300,"T-*"),8)) | L11: =IF(K11="","",IF(SUMPRODUCT((Закрытые!$E$5:$E$300=$B11)*(LEFT(Закрытые!$B$5:$B$300,2)="T-")*(COUNTIF(Торговля!$B$5:$B$300,Закрытые!$B$5:$B$300)=0)*((Закрытые!$F$5:$F$300+Закрытые!$I$5:$I$300-ABS(Закрытые!$F$5:$F$300-Закрытые!$I$5:$I$300))/2)*Закрытые!$G$5:$G$300)<=0,0,ROUND(K11/SUMPRODUCT((Закрытые!$E$5:$E$300=$B11)*(LEFT(Закрытые!$B$5:$B$300,2)="T-")*(COUNTIF(Торговля!$B$5:$B$300,Закрытые!$B$5:$B$300)=0)*((Закрытые!$F$5:$F$300+Закрытые!$I$5:$I$300-ABS(Закрытые!$F$5:$F$300-Закрытые!$I$5:$I$300))/2)*Закрытые!$G$5:$G$300)*100,2))) | M11: =IF(OR(ROUND(N(C11)-N(F11),8)=0,1-N(Ввод!$E$17)/100<=0),"",IF(N(C11)>N(F11),(N(E11)-N(H11))/((N(C11)-N(F11))*(1-N(Ввод!$E$17)/100)),(N(H11)-N(E11))/((N(F11)-N(C11))*(1+N(Ввод!$E$17)/100))))
B12: DASH/BTC | C12: =IF(SUMIFS(Торговля!$F$5:$F$300,Торговля!$E$5:$E$300,$B12)+SUMIFS(Закрытые!$F$5:$F$300,Закрытые!$E$5:$E$300,$B12,Закрытые!$B$5:$B$300,"T-*")=0,"",SUMIFS(Торговля!$F$5:$F$300,Торговля!$E$5:$E$300,$B12)+SUMIFS(Закрытые!$F$5:$F$300,Закрытые!$E$5:$E$300,$B12,Закрытые!$B$5:$B$300,"T-*")) | D12: =IF(C12="","",(SUMPRODUCT((Торговля!$E$5:$E$300=$B12)*Торговля!$F$5:$F$300*Торговля!$G$5:$G$300)+SUMPRODUCT((Закрытые!$E$5:$E$300=$B12)*(LEFT(Закрытые!$B$5:$B$300,2)="T-")*Закрытые!$F$5:$F$300*Закрытые!$G$5:$G$300))/C12) | E12: =IF(C12="","",SUMIFS(Торговля!$H$5:$H$300,Торговля!$E$5:$E$300,$B12)+SUMIFS(Закрытые!$H$5:$H$300,Закрытые!$E$5:$E$300,$B12,Закрытые!$B$5:$B$300,"T-*")) | F12: =IF(SUMIFS(Торговля!$I$5:$I$300,Торговля!$E$5:$E$300,$B12)+SUMIFS(Закрытые!$I$5:$I$300,Закрытые!$E$5:$E$300,$B12,Закрытые!$B$5:$B$300,"T-*")=0,"",SUMIFS(Торговля!$I$5:$I$300,Торговля!$E$5:$E$300,$B12)+SUMIFS(Закрытые!$I$5:$I$300,Закрытые!$E$5:$E$300,$B12,Закрытые!$B$5:$B$300,"T-*")) | G12: =IF(F12="","",(SUMPRODUCT((Торговля!$E$5:$E$300=$B12)*Торговля!$I$5:$I$300*Торговля!$J$5:$J$300)+SUMPRODUCT((Закрытые!$E$5:$E$300=$B12)*(LEFT(Закрытые!$B$5:$B$300,2)="T-")*Закрытые!$I$5:$I$300*Закрытые!$J$5:$J$300))/F12) | H12: =IF(F12="","",SUMIFS(Торговля!$K$5:$K$300,Торговля!$E$5:$E$300,$B12)+SUMIFS(Закрытые!$K$5:$K$300,Закрытые!$E$5:$E$300,$B12,Закрытые!$B$5:$B$300,"T-*")) | I12: =IF($B12="","",IF(COUNTIFS(Торговля!$E$5:$E$300,$B12)+COUNTIFS(Закрытые!$E$5:$E$300,$B12,Закрытые!$B$5:$B$300,"T-*")=0,"",ROUND(SUMIFS(Торговля!$L$5:$L$300,Торговля!$E$5:$E$300,$B12)+SUMIFS(Закрытые!$L$5:$L$300,Закрытые!$E$5:$E$300,$B12,Закрытые!$B$5:$B$300,"T-*"),8))) | J12: =IF($B12="","",IF(COUNTIFS(Торговля!$E$5:$E$300,$B12)+COUNTIFS(Закрытые!$E$5:$E$300,$B12,Закрытые!$B$5:$B$300,"T-*")=0,"",ROUND(SUMIFS(Торговля!$M$5:$M$300,Торговля!$E$5:$E$300,$B12)+SUMIFS(Закрытые!$M$5:$M$300,Закрытые!$E$5:$E$300,$B12,Закрытые!$B$5:$B$300,"T-*"),8))) | K12: =IF($B12="","",ROUND(SUMIFS(Закрытые!$N$5:$N$300,Закрытые!$E$5:$E$300,$B12,Закрытые!$B$5:$B$300,"T-*"),8)) | L12: =IF(K12="","",IF(SUMPRODUCT((Закрытые!$E$5:$E$300=$B12)*(LEFT(Закрытые!$B$5:$B$300,2)="T-")*(COUNTIF(Торговля!$B$5:$B$300,Закрытые!$B$5:$B$300)=0)*((Закрытые!$F$5:$F$300+Закрытые!$I$5:$I$300-ABS(Закрытые!$F$5:$F$300-Закрытые!$I$5:$I$300))/2)*Закрытые!$G$5:$G$300)<=0,0,ROUND(K12/SUMPRODUCT((Закрытые!$E$5:$E$300=$B12)*(LEFT(Закрытые!$B$5:$B$300,2)="T-")*(COUNTIF(Торговля!$B$5:$B$300,Закрытые!$B$5:$B$300)=0)*((Закрытые!$F$5:$F$300+Закрытые!$I$5:$I$300-ABS(Закрытые!$F$5:$F$300-Закрытые!$I$5:$I$300))/2)*Закрытые!$G$5:$G$300)*100,2))) | M12: =IF(OR(ROUND(N(C12)-N(F12),8)=0,1-N(Ввод!$E$17)/100<=0),"",IF(N(C12)>N(F12),(N(E12)-N(H12))/((N(C12)-N(F12))*(1-N(Ввод!$E$17)/100)),(N(H12)-N(E12))/((N(F12)-N(C12))*(1+N(Ввод!$E$17)/100))))
B13: DASH/LTC | C13: =IF(SUMIFS(Торговля!$F$5:$F$300,Торговля!$E$5:$E$300,$B13)+SUMIFS(Закрытые!$F$5:$F$300,Закрытые!$E$5:$E$300,$B13,Закрытые!$B$5:$B$300,"T-*")=0,"",SUMIFS(Торговля!$F$5:$F$300,Торговля!$E$5:$E$300,$B13)+SUMIFS(Закрытые!$F$5:$F$300,Закрытые!$E$5:$E$300,$B13,Закрытые!$B$5:$B$300,"T-*")) | D13: =IF(C13="","",(SUMPRODUCT((Торговля!$E$5:$E$300=$B13)*Торговля!$F$5:$F$300*Торговля!$G$5:$G$300)+SUMPRODUCT((Закрытые!$E$5:$E$300=$B13)*(LEFT(Закрытые!$B$5:$B$300,2)="T-")*Закрытые!$F$5:$F$300*Закрытые!$G$5:$G$300))/C13) | E13: =IF(C13="","",SUMIFS(Торговля!$H$5:$H$300,Торговля!$E$5:$E$300,$B13)+SUMIFS(Закрытые!$H$5:$H$300,Закрытые!$E$5:$E$300,$B13,Закрытые!$B$5:$B$300,"T-*")) | F13: =IF(SUMIFS(Торговля!$I$5:$I$300,Торговля!$E$5:$E$300,$B13)+SUMIFS(Закрытые!$I$5:$I$300,Закрытые!$E$5:$E$300,$B13,Закрытые!$B$5:$B$300,"T-*")=0,"",SUMIFS(Торговля!$I$5:$I$300,Торговля!$E$5:$E$300,$B13)+SUMIFS(Закрытые!$I$5:$I$300,Закрытые!$E$5:$E$300,$B13,Закрытые!$B$5:$B$300,"T-*")) | G13: =IF(F13="","",(SUMPRODUCT((Торговля!$E$5:$E$300=$B13)*Торговля!$I$5:$I$300*Торговля!$J$5:$J$300)+SUMPRODUCT((Закрытые!$E$5:$E$300=$B13)*(LEFT(Закрытые!$B$5:$B$300,2)="T-")*Закрытые!$I$5:$I$300*Закрытые!$J$5:$J$300))/F13) | H13: =IF(F13="","",SUMIFS(Торговля!$K$5:$K$300,Торговля!$E$5:$E$300,$B13)+SUMIFS(Закрытые!$K$5:$K$300,Закрытые!$E$5:$E$300,$B13,Закрытые!$B$5:$B$300,"T-*")) | I13: =IF($B13="","",IF(COUNTIFS(Торговля!$E$5:$E$300,$B13)+COUNTIFS(Закрытые!$E$5:$E$300,$B13,Закрытые!$B$5:$B$300,"T-*")=0,"",ROUND(SUMIFS(Торговля!$L$5:$L$300,Торговля!$E$5:$E$300,$B13)+SUMIFS(Закрытые!$L$5:$L$300,Закрытые!$E$5:$E$300,$B13,Закрытые!$B$5:$B$300,"T-*"),8))) | J13: =IF($B13="","",IF(COUNTIFS(Торговля!$E$5:$E$300,$B13)+COUNTIFS(Закрытые!$E$5:$E$300,$B13,Закрытые!$B$5:$B$300,"T-*")=0,"",ROUND(SUMIFS(Торговля!$M$5:$M$300,Торговля!$E$5:$E$300,$B13)+SUMIFS(Закрытые!$M$5:$M$300,Закрытые!$E$5:$E$300,$B13,Закрытые!$B$5:$B$300,"T-*"),8))) | K13: =IF($B13="","",ROUND(SUMIFS(Закрытые!$N$5:$N$300,Закрытые!$E$5:$E$300,$B13,Закрытые!$B$5:$B$300,"T-*"),8)) | L13: =IF(K13="","",IF(SUMPRODUCT((Закрытые!$E$5:$E$300=$B13)*(LEFT(Закрытые!$B$5:$B$300,2)="T-")*(COUNTIF(Торговля!$B$5:$B$300,Закрытые!$B$5:$B$300)=0)*((Закрытые!$F$5:$F$300+Закрытые!$I$5:$I$300-ABS(Закрытые!$F$5:$F$300-Закрытые!$I$5:$I$300))/2)*Закрытые!$G$5:$G$300)<=0,0,ROUND(K13/SUMPRODUCT((Закрытые!$E$5:$E$300=$B13)*(LEFT(Закрытые!$B$5:$B$300,2)="T-")*(COUNTIF(Торговля!$B$5:$B$300,Закрытые!$B$5:$B$300)=0)*((Закрытые!$F$5:$F$300+Закрытые!$I$5:$I$300-ABS(Закрытые!$F$5:$F$300-Закрытые!$I$5:$I$300))/2)*Закрытые!$G$5:$G$300)*100,2))) | M13: =IF(OR(ROUND(N(C13)-N(F13),8)=0,1-N(Ввод!$E$17)/100<=0),"",IF(N(C13)>N(F13),(N(E13)-N(H13))/((N(C13)-N(F13))*(1-N(Ввод!$E$17)/100)),(N(H13)-N(E13))/((N(F13)-N(C13))*(1+N(Ввод!$E$17)/100))))
B14: DOGE/BTC | C14: =IF(SUMIFS(Торговля!$F$5:$F$300,Торговля!$E$5:$E$300,$B14)+SUMIFS(Закрытые!$F$5:$F$300,Закрытые!$E$5:$E$300,$B14,Закрытые!$B$5:$B$300,"T-*")=0,"",SUMIFS(Торговля!$F$5:$F$300,Торговля!$E$5:$E$300,$B14)+SUMIFS(Закрытые!$F$5:$F$300,Закрытые!$E$5:$E$300,$B14,Закрытые!$B$5:$B$300,"T-*")) | D14: =IF(C14="","",(SUMPRODUCT((Торговля!$E$5:$E$300=$B14)*Торговля!$F$5:$F$300*Торговля!$G$5:$G$300)+SUMPRODUCT((Закрытые!$E$5:$E$300=$B14)*(LEFT(Закрытые!$B$5:$B$300,2)="T-")*Закрытые!$F$5:$F$300*Закрытые!$G$5:$G$300))/C14) | E14: =IF(C14="","",SUMIFS(Торговля!$H$5:$H$300,Торговля!$E$5:$E$300,$B14)+SUMIFS(Закрытые!$H$5:$H$300,Закрытые!$E$5:$E$300,$B14,Закрытые!$B$5:$B$300,"T-*")) | F14: =IF(SUMIFS(Торговля!$I$5:$I$300,Торговля!$E$5:$E$300,$B14)+SUMIFS(Закрытые!$I$5:$I$300,Закрытые!$E$5:$E$300,$B14,Закрытые!$B$5:$B$300,"T-*")=0,"",SUMIFS(Торговля!$I$5:$I$300,Торговля!$E$5:$E$300,$B14)+SUMIFS(Закрытые!$I$5:$I$300,Закрытые!$E$5:$E$300,$B14,Закрытые!$B$5:$B$300,"T-*")) | G14: =IF(F14="","",(SUMPRODUCT((Торговля!$E$5:$E$300=$B14)*Торговля!$I$5:$I$300*Торговля!$J$5:$J$300)+SUMPRODUCT((Закрытые!$E$5:$E$300=$B14)*(LEFT(Закрытые!$B$5:$B$300,2)="T-")*Закрытые!$I$5:$I$300*Закрытые!$J$5:$J$300))/F14) | H14: =IF(F14="","",SUMIFS(Торговля!$K$5:$K$300,Торговля!$E$5:$E$300,$B14)+SUMIFS(Закрытые!$K$5:$K$300,Закрытые!$E$5:$E$300,$B14,Закрытые!$B$5:$B$300,"T-*")) | I14: =IF($B14="","",IF(COUNTIFS(Торговля!$E$5:$E$300,$B14)+COUNTIFS(Закрытые!$E$5:$E$300,$B14,Закрытые!$B$5:$B$300,"T-*")=0,"",ROUND(SUMIFS(Торговля!$L$5:$L$300,Торговля!$E$5:$E$300,$B14)+SUMIFS(Закрытые!$L$5:$L$300,Закрытые!$E$5:$E$300,$B14,Закрытые!$B$5:$B$300,"T-*"),8))) | J14: =IF($B14="","",IF(COUNTIFS(Торговля!$E$5:$E$300,$B14)+COUNTIFS(Закрытые!$E$5:$E$300,$B14,Закрытые!$B$5:$B$300,"T-*")=0,"",ROUND(SUMIFS(Торговля!$M$5:$M$300,Торговля!$E$5:$E$300,$B14)+SUMIFS(Закрытые!$M$5:$M$300,Закрытые!$E$5:$E$300,$B14,Закрытые!$B$5:$B$300,"T-*"),8))) | K14: =IF($B14="","",ROUND(SUMIFS(Закрытые!$N$5:$N$300,Закрытые!$E$5:$E$300,$B14,Закрытые!$B$5:$B$300,"T-*"),8)) | L14: =IF(K14="","",IF(SUMPRODUCT((Закрытые!$E$5:$E$300=$B14)*(LEFT(Закрытые!$B$5:$B$300,2)="T-")*(COUNTIF(Торговля!$B$5:$B$300,Закрытые!$B$5:$B$300)=0)*((Закрытые!$F$5:$F$300+Закрытые!$I$5:$I$300-ABS(Закрытые!$F$5:$F$300-Закрытые!$I$5:$I$300))/2)*Закрытые!$G$5:$G$300)<=0,0,ROUND(K14/SUMPRODUCT((Закрытые!$E$5:$E$300=$B14)*(LEFT(Закрытые!$B$5:$B$300,2)="T-")*(COUNTIF(Торговля!$B$5:$B$300,Закрытые!$B$5:$B$300)=0)*((Закрытые!$F$5:$F$300+Закрытые!$I$5:$I$300-ABS(Закрытые!$F$5:$F$300-Закрытые!$I$5:$I$300))/2)*Закрытые!$G$5:$G$300)*100,2))) | M14: =IF(OR(ROUND(N(C14)-N(F14),8)=0,1-N(Ввод!$E$17)/100<=0),"",IF(N(C14)>N(F14),(N(E14)-N(H14))/((N(C14)-N(F14))*(1-N(Ввод!$E$17)/100)),(N(H14)-N(E14))/((N(F14)-N(C14))*(1+N(Ввод!$E$17)/100))))
